Workbook

Sheet Instrucciones
B2: Finanzas de la agencia
B4: Cómo funciona
B5: 1. Configuración: pon el nombre de cada socia, el % de reparto (50/50 por defecto), el IVA (21 %), el IRPF (15 %) y el año.
B6: Añade también la lista de tus clientes: luego los elegirás en un desplegable.
B7: 2. Cobros: cada vez que un cliente te pague, añade una fila: fecha, cliente, concepto, importe y forma de pago.
B8: Las columnas grises se calculan solas: base, IVA, total con IVA, IRPF, neto y lo que le toca a cada socia.
B9: 3. Resumen mensual: mes a mes, lo facturado, el IVA, el IRPF, el neto de cada socia y cuánto entró en efectivo y por transferencia.
B10: Debajo tienes el resumen por trimestres (útil para los modelos 303 de IVA y 130 de IRPF).
B11: 4. Detalle del mes: elige un mes y ves el reparto entre socias y lo que ha pagado cada cliente ese mes.
B12: 5. Por cliente: cuánto ha pagado cada cliente cada mes del año.
B14: Cómo se calcula
B15: Base imponible = el importe sin IVA (si en Configuración dices que tus importes ya llevan IVA, se lo quita: importe / 1,21).
... B26: Este libro calcula sobre los ingresos. No resta gastos de la agencia, así que el IRPF es una estimación para apartar, no la cifra exacta a pagar.

Sheet Configuración
A1: Configuración
A3: Socias | B3: Nombre | C3: % del reparto
A4: Socia 1 | B4: Socia 1 | C4: 0.5 | D4: ← cambia los nombres y el % de la socia 1; el de la socia 2 se ajusta solo
A5: Socia 2 | B5: Socia 2 | C5: =1-C4 -> 0.5
A7: Impuestos y opciones | B7: Valor
A8: IVA | B8: 0.21 | C8: Tipo general en España
A9: IRPF | B9: 0.15 | C9: 15 % general (7 % los primeros años de actividad). Cámbialo si tu gestoría te indica otro
A10: ¿Los importes que apunto ya llevan IVA? | B10: No | C10: "No" = apuntas la cantidad sin IVA (la base). "Sí" = apuntas el total que paga el cliente con IVA
A12: Año a analizar | B12: Año
A13: Año de los resúmenes | B13: 2026
A15: Clientes | C15: Formas de pago
A16: Cliente A (ejemplo) | C16: Transferencia
A17: Cliente B (ejemplo) | C17: Efectivo
A18: Cliente C (ejemplo) | C18: Bizum
A19: Cliente D (ejemplo)

Sheet Cobros
A1: Fecha | B1: Cliente | C1: Concepto | D1: Importe (€) | E1: Forma de pago | F1: Base imponible (€) | G1: IVA (€) | H1: Total con IVA (€) | I1: IRPF (€) | J1: Neto (€) | K1: ="Neto "&Configuración!$B$4 -> Neto Socia 1 | L1: ="Neto "&Configuración!$B$5 -> Neto Socia 2
A2: 46266 | B2: Cliente A (ejemplo) | C2: Gestión redes sociales septiembre | D2: 1200 | E2: Transferencia | F2: =IF($D2="","",IF(Configuración!$B$10="Sí",$D2/(1+Configuración!$B$8),$D2)) -> 1200 | G2: =IF($D2="","",F2*Configuración!$B$8) -> 252 | H2: =IF($D2="","",F2+G2) -> 1452 | I2: =IF($D2="","",F2*Configuración!$B$9) -> 180 | J2: =IF($D2="","",F2-I2) -> 1020 | K2: =IF($D2="","",J2*Configuración!$C$4) -> 510 | L2: =IF($D2="","",J2*Configuración!$C$5) -> 510
A3: 46270 | B3: Cliente B (ejemplo) | C3: Campaña Meta Ads | D3: 800 | E3: Efectivo | F3: =IF($D3="","",IF(Configuración!$B$10="Sí",$D3/(1+Configuración!$B$8),$D3)) -> 800 | G3: =IF($D3="","",F3*Configuración!$B$8) -> 168 | H3: =IF($D3="","",F3+G3) -> 968 | I3: =IF($D3="","",F3*Configuración!$B$9) -> 120 | J3: =IF($D3="","",F3-I3) -> 680 | K3: =IF($D3="","",J3*Configuración!$C$4) -> 340 | L3: =IF($D3="","",J3*Configuración!$C$5) -> 340
A4: 46296 | B4: Cliente A (ejemplo) | C4: Gestión redes sociales octubre | D4: 1200 | E4: Transferencia | F4: =IF($D4="","",IF(Configuración!$B$10="Sí",$D4/(1+Configuración!$B$8),$D4)) -> 1200 | G4: =IF($D4="","",F4*Configuración!$B$8) -> 252 | H4: =IF($D4="","",F4+G4) -> 1452 | I4: =IF($D4="","",F4*Configuración!$B$9) -> 180 | J4: =IF($D4="","",F4-I4) -> 1020 | K4: =IF($D4="","",J4*Configuración!$C$4) -> 510 | L4: =IF($D4="","",J4*Configuración!$C$5) -> 510
A5: 46298 | B5: Cliente B (ejemplo) | C5: Campaña Meta Ads | D5: 800 | E5: Efectivo | F5: =IF($D5="","",IF(Configuración!$B$10="Sí",$D5/(1+Configuración!$B$8),$D5)) -> 800 | G5: =IF($D5="","",F5*Configuración!$B$8) -> 168 | H5: =IF($D5="","",F5+G5) -> 968 | I5: =IF($D5="","",F5*Configuración!$B$9) -> 120 | J5: =IF($D5="","",F5-I5) -> 680 | K5: =IF($D5="","",J5*Configuración!$C$4) -> 340 | L5: =IF($D5="","",J5*Configuración!$C$5) -> 340
A6: 46305 | B6: Cliente C (ejemplo) | C6: Diseño web | D6: 1500 | E6: Transferencia | F6: =IF($D6="","",IF(Configuración!$B$10="Sí",$D6/(1+Configuración!$B$8),$D6)) -> 1500 | G6: =IF($D6="","",F6*Configuración!$B$8) -> 315 | H6: =IF($D6="","",F6+G6) -> 1815 | I6: =IF($D6="","",F6*Configuración!$B$9) -> 225 | J6: =IF($D6="","",F6-I6) -> 1275 | K6: =IF($D6="","",J6*Configuración!$C$4) -> 637.5 | L6: =IF($D6="","",J6*Configuración!$C$5) -> 637.5
F7: =IF($D7="","",IF(Configuración!$B$10="Sí",$D7/(1+Configuración!$B$8),$D7)) | G7: =IF($D7="","",F7*Configuración!$B$8) | H7: =IF($D7="","",F7+G7) | I7: =IF($D7="","",F7*Configuración!$B$9) | J7: =IF($D7="","",F7-I7) | K7: =IF($D7="","",J7*Configuración!$C$4) | L7: =IF($D7="","",J7*Configuración!$C$5)
F8: =IF($D8="","",IF(Configuración!$B$10="Sí",$D8/(1+Configuración!$B$8),$D8)) | G8: =IF($D8="","",F8*Configuración!$B$8) | H8: =IF($D8="","",F8+G8) | I8: =IF($D8="","",F8*Configuración!$B$9) | J8: =IF($D8="","",F8-I8) | K8: =IF($D8="","",J8*Configuración!$C$4) | L8: =IF($D8="","",J8*Configuración!$C$5)
F9: =IF($D9="","",IF(Configuración!$B$10="Sí",$D9/(1+Configuración!$B$8),$D9)) | G9: =IF($D9="","",F9*Configuración!$B$8) | H9: =IF($D9="","",F9+G9) | I9: =IF($D9="","",F9*Configuración!$B$9) | J9: =IF($D9="","",F9-I9) | K9: =IF($D9="","",J9*Configuración!$C$4) | L9: =IF($D9="","",J9*Configuración!$C$5)
F10: =IF($D10="","",IF(Configuración!$B$10="Sí",$D10/(1+Configuración!$B$8),$D10)) | G10: =IF($D10="","",F10*Configuración!$B$8) | H10: =IF($D10="","",F10+G10) | I10: =IF($D10="","",F10*Configuración!$B$9) | J10: =IF($D10="","",F10-I10) | K10: =IF($D10="","",J10*Configuración!$C$4) | L10: =IF($D10="","",J10*Configuración!$C$5)
F11: =IF($D11="","",IF(Configuración!$B$10="Sí",$D11/(1+Configuración!$B$8),$D11)) | G11: =IF($D11="","",F11*Configuración!$B$8) | H11: =IF($D11="","",F11+G11) | I11: =IF($D11="","",F11*Configuración!$B$9) | J11: =IF($D11="","",F11-I11) | K11: =IF($D11="","",J11*Configuración!$C$4) | L11: =IF($D11="","",J11*Configuración!$C$5)
F12: =IF($D12="","",IF(Configuración!$B$10="Sí",$D12/(1+Configuración!$B$8),$D12)) | G12: =IF($D12="","",F12*Configuración!$B$8) | H12: =IF($D12="","",F12+G12) | I12: =IF($D12="","",F12*Configuración!$B$9) | J12: =IF($D12="","",F12-I12) | K12: =IF($D12="","",J12*Configuración!$C$4) | L12: =IF($D12="","",J12*Configuración!$C$5)
F13: =IF($D13="","",IF(Configuración!$B$10="Sí",$D13/(1+Configuración!$B$8),$D13)) | G13: =IF($D13="","",F13*Configuración!$B$8) | H13: =IF($D13="","",F13+G13) | I13: =IF($D13="","",F13*Configuración!$B$9) | J13: =IF($D13="","",F13-I13) | K13: =IF($D13="","",J13*Configuración!$C$4) | L13: =IF($D13="","",J13*Configuración!$C$5)
F14: =IF($D14="","",IF(Configuración!$B$10="Sí",$D14/(1+Configuración!$B$8),$D14)) | G14: =IF($D14="","",F14*Configuración!$B$8) | H14: =IF($D14="","",F14+G14) | I14: =IF($D14="","",F14*Configuración!$B$9) | J14: =IF($D14="","",F14-I14) | K14: =IF($D14="","",J14*Configuración!$C$4) | L14: =IF($D14="","",J14*Configuración!$C$5)
F15: =IF($D15="","",IF(Configuración!$B$10="Sí",$D15/(1+Configuración!$B$8),$D15)) | G15: =IF($D15="","",F15*Configuración!$B$8) | H15: =IF($D15="","",F15+G15) | I15: =IF($D15="","",F15*Configuración!$B$9) | J15: =IF($D15="","",F15-I15) | K15: =IF($D15="","",J15*Configuración!$C$4) | L15: =IF($D15="","",J15*Configuración!$C$5)
F16: =IF($D16="","",IF(Configuración!$B$10="Sí",$D16/(1+Configuración!$B$8),$D16)) | G16: =IF($D16="","",F16*Configuración!$B$8) | H16: =IF($D16="","",F16+G16) | I16: =IF($D16="","",F16*Configuración!$B$9) | J16: =IF($D16="","",F16-I16) | K16: =IF($D16="","",J16*Configuración!$C$4) | L16: =IF($D16="","",J16*Configuración!$C$5)
F17: =IF($D17="","",IF(Configuración!$B$10="Sí",$D17/(1+Configuración!$B$8),$D17)) | G17: =IF($D17="","",F17*Configuración!$B$8) | H17: =IF($D17="","",F17+G17) | I17: =IF($D17="","",F17*Configuración!$B$9) | J17: =IF($D17="","",F17-I17) | K17: =IF($D17="","",J17*Configuración!$C$4) | L17: =IF($D17="","",J17*Configuración!$C$5)
F18: =IF($D18="","",IF(Configuración!$B$10="Sí",$D18/(1+Configuración!$B$8),$D18)) | G18: =IF($D18="","",F18*Configuración!$B$8) | H18: =IF($D18="","",F18+G18) | I18: =IF($D18="","",F18*Configuración!$B$9) | J18: =IF($D18="","",F18-I18) | K18: =IF($D18="","",J18*Configuración!$C$4) | L18: =IF($D18="","",J18*Configuración!$C$5)
... F501: =IF($D501="","",IF(Configuración!$B$10="Sí",$D501/(1+Configuración!$B$8),$D501)) | G501: =IF($D501="","",F501*Configuración!$B$8) | H501: =IF($D501="","",F501+G501) | I501: =IF($D501="","",F501*Configuración!$B$9) | J501: =IF($D501="","",F501-I501) | K501: =IF($D501="","",J501*Configuración!$C$4) | L501: =IF($D501="","",J501*Configuración!$C$5)

Sheet Resumen mensual
A1: Resumen mensual
A2: Año | B2: =Configuración!$B$13 -> 2026 | C2: (se cambia en Configuración)
A3: Cobros sin fecha | B3: =COUNTIFS(Cobros!$D$2:$D$501,">0",Cobros!$A$2:$A$501,"") -> 0 | C3: ← si no es 0, hay importes sin fecha que no salen en los resúmenes
A5: Mes | B5: Nº cobros | C5: Base imponible (€) | D5: IVA (€) | E5: Total con IVA (€) | F5: IRPF (€) | G5: Neto (€) | H5: ="Neto "&Configuración!$B$4&" (€)" -> Neto Socia 1 (€) | I5: ="Neto "&Configuración!$B$5&" (€)" -> Neto Socia 2 (€) | J5: Cobrado en efectivo (€) | K5: Cobrado por transferencia (€)
A6: Enero | B6: =COUNTIFS(Cobros!$A$2:$A$501,">="&DATE($B$2,1,1),Cobros!$A$2:$A$501,"<"&DATE($B$2,1+1,1)) -> 0 | C6: =SUMIFS(Cobros!$F$2:$F$501,Cobros!$A$2:$A$501,">="&DATE($B$2,1,1),Cobros!$A$2:$A$501,"<"&DATE($B$2,1+1,1)) -> 0 | D6: =SUMIFS(Cobros!$G$2:$G$501,Cobros!$A$2:$A$501,">="&DATE($B$2,1,1),Cobros!$A$2:$A$501,"<"&DATE($B$2,1+1,1)) -> 0 | E6: =SUMIFS(Cobros!$H$2:$H$501,Cobros!$A$2:$A$501,">="&DATE($B$2,1,1),Cobros!$A$2:$A$501,"<"&DATE($B$2,1+1,1)) -> 0 | F6: =SUMIFS(Cobros!$I$2:$I$501,Cobros!$A$2:$A$501,">="&DATE($B$2,1,1),Cobros!$A$2:$A$501,"<"&DATE($B$2,1+1,1)) -> 0 | G6: =SUMIFS(Cobros!$J$2:$J$501,Cobros!$A$2:$A$501,">="&DATE($B$2,1,1),Cobros!$A$2:$A$501,"<"&DATE($B$2,1+1,1)) -> 0 | H6: =SUMIFS(Cobros!$K$2:$K$501,Cobros!$A$2:$A$501,">="&DATE($B$2,1,1),Cobros!$A$2:$A$501,"<"&DATE($B$2,1+1,1)) -> 0 | I6: =SUMIFS(Cobros!$L$2:$L$501,Cobros!$A$2:$A$501,">="&DATE($B$2,1,1),Cobros!$A$2:$A$501,"<"&DATE($B$2,1+1,1)) -> 0 | J6: =SUMIFS(Cobros!$H$2:$H$501,Cobros!$E$2:$E$501,"Efectivo",Cobros!$A$2:$A$501,">="&DATE($B$2,1,1),Cobros!$A$2:$A$501,"<"&DATE($B$2,1+1,1)) -> 0 | K6: =SUMIFS(Cobros!$H$2:$H$501,Cobros!$E$2:$E$501,"Transferencia",Cobros!$A$2:$A$501,">="&DATE($B$2,1,1),Cobros!$A$2:$A$501,"<"&DATE($B$2,1+1,1)) -> 0
A7: Febrero | B7: =COUNTIFS(Cobros!$A$2:$A$501,">="&DATE($B$2,2,1),Cobros!$A$2:$A$501,"<"&DATE($B$2,2+1,1)) -> 0 | C7: =SUMIFS(Cobros!$F$2:$F$501,Cobros!$A$2:$A$501,">="&DATE($B$2,2,1),Cobros!$A$2:$A$501,"<"&DATE($B$2,2+1,1)) -> 0 | D7: =SUMIFS(Cobros!$G$2:$G$501,Cobros!$A$2:$A$501,">="&DATE($B$2,2,1),Cobros!$A$2:$A$501,"<"&DATE($B$2,2+1,1)) -> 0 | E7: =SUMIFS(Cobros!$H$2:$H$501,Cobros!$A$2:$A$501,">="&DATE($B$2,2,1),Cobros!$A$2:$A$501,"<"&DATE($B$2,2+1,1)) -> 0 | F7: =SUMIFS(Cobros!$I$2:$I$501,Cobros!$A$2:$A$501,">="&DATE($B$2,2,1),Cobros!$A$2:$A$501,"<"&DATE($B$2,2+1,1)) -> 0 | G7: =SUMIFS(Cobros!$J$2:$J$501,Cobros!$A$2:$A$501,">="&DATE($B$2,2,1),Cobros!$A$2:$A$501,"<"&DATE($B$2,2+1,1)) -> 0 | H7: =SUMIFS(Cobros!$K$2:$K$501,Cobros!$A$2:$A$501,">="&DATE($B$2,2,1),Cobros!$A$2:$A$501,"<"&DATE($B$2,2+1,1)) -> 0 | I7: =SUMIFS(Cobros!$L$2:$L$501,Cobros!$A$2:$A$501,">="&DATE($B$2,2,1),Cobros!$A$2:$A$501,"<"&DATE($B$2,2+1,1)) -> 0 | J7: =SUMIFS(Cobros!$H$2:$H$501,Cobros!$E$2:$E$501,"Efectivo",Cobros!$A$2:$A$501,">="&DATE($B$2,2,1),Cobros!$A$2:$A$501,"<"&DATE($B$2,2+1,1)) -> 0 | K7: =SUMIFS(Cobros!$H$2:$H$501,Cobros!$E$2:$E$501,"Transferencia",Cobros!$A$2:$A$501,">="&DATE($B$2,2,1),Cobros!$A$2:$A$501,"<"&DATE($B$2,2+1,1)) -> 0
A8: Marzo | B8: =COUNTIFS(Cobros!$A$2:$A$501,">="&DATE($B$2,3,1),Cobros!$A$2:$A$501,"<"&DATE($B$2,3+1,1)) -> 0 | C8: =SUMIFS(Cobros!$F$2:$F$501,Cobros!$A$2:$A$501,">="&DATE($B$2,3,1),Cobros!$A$2:$A$501,"<"&DATE($B$2,3+1,1)) -> 0 | D8: =SUMIFS(Cobros!$G$2:$G$501,Cobros!$A$2:$A$501,">="&DATE($B$2,3,1),Cobros!$A$2:$A$501,"<"&DATE($B$2,3+1,1)) -> 0 | E8: =SUMIFS(Cobros!$H$2:$H$501,Cobros!$A$2:$A$501,">="&DATE($B$2,3,1),Cobros!$A$2:$A$501,"<"&DATE($B$2,3+1,1)) -> 0 | F8: =SUMIFS(Cobros!$I$2:$I$501,Cobros!$A$2:$A$501,">="&DATE($B$2,3,1),Cobros!$A$2:$A$501,"<"&DATE($B$2,3+1,1)) -> 0 | G8: =SUMIFS(Cobros!$J$2:$J$501,Cobros!$A$2:$A$501,">="&DATE($B$2,3,1),Cobros!$A$2:$A$501,"<"&DATE($B$2,3+1,1)) -> 0 | H8: =SUMIFS(Cobros!$K$2:$K$501,Cobros!$A$2:$A$501,">="&DATE($B$2,3,1),Cobros!$A$2:$A$501,"<"&DATE($B$2,3+1,1)) -> 0 | I8: =SUMIFS(Cobros!$L$2:$L$501,Cobros!$A$2:$A$501,">="&DATE($B$2,3,1),Cobros!$A$2:$A$501,"<"&DATE($B$2,3+1,1)) -> 0 | J8: =SUMIFS(Cobros!$H$2:$H$501,Cobros!$E$2:$E$501,"Efectivo",Cobros!$A$2:$A$501,">="&DATE($B$2,3,1),Cobros!$A$2:$A$501,"<"&DATE($B$2,3+1,1)) -> 0 | K8: =SUMIFS(Cobros!$H$2:$H$501,Cobros!$E$2:$E$501,"Transferencia",Cobros!$A$2:$A$501,">="&DATE($B$2,3,1),Cobros!$A$2:$A$501,"<"&DATE($B$2,3+1,1)) -> 0
A9: Abril | B9: =COUNTIFS(Cobros!$A$2:$A$501,">="&DATE($B$2,4,1),Cobros!$A$2:$A$501,"<"&DATE($B$2,4+1,1)) -> 0 | C9: =SUMIFS(Cobros!$F$2:$F$501,Cobros!$A$2:$A$501,">="&DATE($B$2,4,1),Cobros!$A$2:$A$501,"<"&DATE($B$2,4+1,1)) -> 0 | D9: =SUMIFS(Cobros!$G$2:$G$501,Cobros!$A$2:$A$501,">="&DATE($B$2,4,1),Cobros!$A$2:$A$501,"<"&DATE($B$2,4+1,1)) -> 0 | E9: =SUMIFS(Cobros!$H$2:$H$501,Cobros!$A$2:$A$501,">="&DATE($B$2,4,1),Cobros!$A$2:$A$501,"<"&DATE($B$2,4+1,1)) -> 0 | F9: =SUMIFS(Cobros!$I$2:$I$501,Cobros!$A$2:$A$501,">="&DATE($B$2,4,1),Cobros!$A$2:$A$501,"<"&DATE($B$2,4+1,1)) -> 0 | G9: =SUMIFS(Cobros!$J$2:$J$501,Cobros!$A$2:$A$501,">="&DATE($B$2,4,1),Cobros!$A$2:$A$501,"<"&DATE($B$2,4+1,1)) -> 0 | H9: =SUMIFS(Cobros!$K$2:$K$501,Cobros!$A$2:$A$501,">="&DATE($B$2,4,1),Cobros!$A$2:$A$501,"<"&DATE($B$2,4+1,1)) -> 0 | I9: =SUMIFS(Cobros!$L$2:$L$501,Cobros!$A$2:$A$501,">="&DATE($B$2,4,1),Cobros!$A$2:$A$501,"<"&DATE($B$2,4+1,1)) -> 0 | J9: =SUMIFS(Cobros!$H$2:$H$501,Cobros!$E$2:$E$501,"Efectivo",Cobros!$A$2:$A$501,">="&DATE($B$2,4,1),Cobros!$A$2:$A$501,"<"&DATE($B$2,4+1,1)) -> 0 | K9: =SUMIFS(Cobros!$H$2:$H$501,Cobros!$E$2:$E$501,"Transferencia",Cobros!$A$2:$A$501,">="&DATE($B$2,4,1),Cobros!$A$2:$A$501,"<"&DATE($B$2,4+1,1)) -> 0
A10: Mayo | B10: =COUNTIFS(Cobros!$A$2:$A$501,">="&DATE($B$2,5,1),Cobros!$A$2:$A$501,"<"&DATE($B$2,5+1,1)) -> 0 | C10: =SUMIFS(Cobros!$F$2:$F$501,Cobros!$A$2:$A$501,">="&DATE($B$2,5,1),Cobros!$A$2:$A$501,"<"&DATE($B$2,5+1,1)) -> 0 | D10: =SUMIFS(Cobros!$G$2:$G$501,Cobros!$A$2:$A$501,">="&DATE($B$2,5,1),Cobros!$A$2:$A$501,"<"&DATE($B$2,5+1,1)) -> 0 | E10: =SUMIFS(Cobros!$H$2:$H$501,Cobros!$A$2:$A$501,">="&DATE($B$2,5,1),Cobros!$A$2:$A$501,"<"&DATE($B$2,5+1,1)) -> 0 | F10: =SUMIFS(Cobros!$I$2:$I$501,Cobros!$A$2:$A$501,">="&DATE($B$2,5,1),Cobros!$A$2:$A$501,"<"&DATE($B$2,5+1,1)) -> 0 | G10: =SUMIFS(Cobros!$J$2:$J$501,Cobros!$A$2:$A$501,">="&DATE($B$2,5,1),Cobros!$A$2:$A$501,"<"&DATE($B$2,5+1,1)) -> 0 | H10: =SUMIFS(Cobros!$K$2:$K$501,Cobros!$A$2:$A$501,">="&DATE($B$2,5,1),Cobros!$A$2:$A$501,"<"&DATE($B$2,5+1,1)) -> 0 | I10: =SUMIFS(Cobros!$L$2:$L$501,Cobros!$A$2:$A$501,">="&DATE($B$2,5,1),Cobros!$A$2:$A$501,"<"&DATE($B$2,5+1,1)) -> 0 | J10: =SUMIFS(Cobros!$H$2:$H$501,Cobros!$E$2:$E$501,"Efectivo",Cobros!$A$2:$A$501,">="&DATE($B$2,5,1),Cobros!$A$2:$A$501,"<"&DATE($B$2,5+1,1)) -> 0 | K10: =SUMIFS(Cobros!$H$2:$H$501,Cobros!$E$2:$E$501,"Transferencia",Cobros!$A$2:$A$501,">="&DATE($B$2,5,1),Cobros!$A$2:$A$501,"<"&DATE($B$2,5+1,1)) -> 0
A11: Junio | B11: =COUNTIFS(Cobros!$A$2:$A$501,">="&DATE($B$2,6,1),Cobros!$A$2:$A$501,"<"&DATE($B$2,6+1,1)) -> 0 | C11: =SUMIFS(Cobros!$F$2:$F$501,Cobros!$A$2:$A$501,">="&DATE($B$2,6,1),Cobros!$A$2:$A$501,"<"&DATE($B$2,6+1,1)) -> 0 | D11: =SUMIFS(Cobros!$G$2:$G$501,Cobros!$A$2:$A$501,">="&DATE($B$2,6,1),Cobros!$A$2:$A$501,"<"&DATE($B$2,6+1,1)) -> 0 | E11: =SUMIFS(Cobros!$H$2:$H$501,Cobros!$A$2:$A$501,">="&DATE($B$2,6,1),Cobros!$A$2:$A$501,"<"&DATE($B$2,6+1,1)) -> 0 | F11: =SUMIFS(Cobros!$I$2:$I$501,Cobros!$A$2:$A$501,">="&DATE($B$2,6,1),Cobros!$A$2:$A$501,"<"&DATE($B$2,6+1,1)) -> 0 | G11: =SUMIFS(Cobros!$J$2:$J$501,Cobros!$A$2:$A$501,">="&DATE($B$2,6,1),Cobros!$A$2:$A$501,"<"&DATE($B$2,6+1,1)) -> 0 | H11: =SUMIFS(Cobros!$K$2:$K$501,Cobros!$A$2:$A$501,">="&DATE($B$2,6,1),Cobros!$A$2:$A$501,"<"&DATE($B$2,6+1,1)) -> 0 | I11: =SUMIFS(Cobros!$L$2:$L$501,Cobros!$A$2:$A$501,">="&DATE($B$2,6,1),Cobros!$A$2:$A$501,"<"&DATE($B$2,6+1,1)) -> 0 | J11: =SUMIFS(Cobros!$H$2:$H$501,Cobros!$E$2:$E$501,"Efectivo",Cobros!$A$2:$A$501,">="&DATE($B$2,6,1),Cobros!$A$2:$A$501,"<"&DATE($B$2,6+1,1)) -> 0 | K11: =SUMIFS(Cobros!$H$2:$H$501,Cobros!$E$2:$E$501,"Transferencia",Cobros!$A$2:$A$501,">="&DATE($B$2,6,1),Cobros!$A$2:$A$501,"<"&DATE($B$2,6+1,1)) -> 0
A12: Julio | B12: =COUNTIFS(Cobros!$A$2:$A$501,">="&DATE($B$2,7,1),Cobros!$A$2:$A$501,"<"&DATE($B$2,7+1,1)) -> 0 | C12: =SUMIFS(Cobros!$F$2:$F$501,Cobros!$A$2:$A$501,">="&DATE($B$2,7,1),Cobros!$A$2:$A$501,"<"&DATE($B$2,7+1,1)) -> 0 | D12: =SUMIFS(Cobros!$G$2:$G$501,Cobros!$A$2:$A$501,">="&DATE($B$2,7,1),Cobros!$A$2:$A$501,"<"&DATE($B$2,7+1,1)) -> 0 | E12: =SUMIFS(Cobros!$H$2:$H$501,Cobros!$A$2:$A$501,">="&DATE($B$2,7,1),Cobros!$A$2:$A$501,"<"&DATE($B$2,7+1,1)) -> 0 | F12: =SUMIFS(Cobros!$I$2:$I$501,Cobros!$A$2:$A$501,">="&DATE($B$2,7,1),Cobros!$A$2:$A$501,"<"&DATE($B$2,7+1,1)) -> 0 | G12: =SUMIFS(Cobros!$J$2:$J$501,Cobros!$A$2:$A$501,">="&DATE($B$2,7,1),Cobros!$A$2:$A$501,"<"&DATE($B$2,7+1,1)) -> 0 | H12: =SUMIFS(Cobros!$K$2:$K$501,Cobros!$A$2:$A$501,">="&DATE($B$2,7,1),Cobros!$A$2:$A$501,"<"&DATE($B$2,7+1,1)) -> 0 | I12: =SUMIFS(Cobros!$L$2:$L$501,Cobros!$A$2:$A$501,">="&DATE($B$2,7,1),Cobros!$A$2:$A$501,"<"&DATE($B$2,7+1,1)) -> 0 | J12: =SUMIFS(Cobros!$H$2:$H$501,Cobros!$E$2:$E$501,"Efectivo",Cobros!$A$2:$A$501,">="&DATE($B$2,7,1),Cobros!$A$2:$A$501,"<"&DATE($B$2,7+1,1)) -> 0 | K12: =SUMIFS(Cobros!$H$2:$H$501,Cobros!$E$2:$E$501,"Transferencia",Cobros!$A$2:$A$501,">="&DATE($B$2,7,1),Cobros!$A$2:$A$501,"<"&DATE($B$2,7+1,1)) -> 0
A13: Agosto | B13: =COUNTIFS(Cobros!$A$2:$A$501,">="&DATE($B$2,8,1),Cobros!$A$2:$A$501,"<"&DATE($B$2,8+1,1)) -> 0 | C13: =SUMIFS(Cobros!$F$2:$F$501,Cobros!$A$2:$A$501,">="&DATE($B$2,8,1),Cobros!$A$2:$A$501,"<"&DATE($B$2,8+1,1)) -> 0 | D13: =SUMIFS(Cobros!$G$2:$G$501,Cobros!$A$2:$A$501,">="&DATE($B$2,8,1),Cobros!$A$2:$A$501,"<"&DATE($B$2,8+1,1)) -> 0 | E13: =SUMIFS(Cobros!$H$2:$H$501,Cobros!$A$2:$A$501,">="&DATE($B$2,8,1),Cobros!$A$2:$A$501,"<"&DATE($B$2,8+1,1)) -> 0 | F13: =SUMIFS(Cobros!$I$2:$I$501,Cobros!$A$2:$A$501,">="&DATE($B$2,8,1),Cobros!$A$2:$A$501,"<"&DATE($B$2,8+1,1)) -> 0 | G13: =SUMIFS(Cobros!$J$2:$J$501,Cobros!$A$2:$A$501,">="&DATE($B$2,8,1),Cobros!$A$2:$A$501,"<"&DATE($B$2,8+1,1)) -> 0 | H13: =SUMIFS(Cobros!$K$2:$K$501,Cobros!$A$2:$A$501,">="&DATE($B$2,8,1),Cobros!$A$2:$A$501,"<"&DATE($B$2,8+1,1)) -> 0 | I13: =SUMIFS(Cobros!$L$2:$L$501,Cobros!$A$2:$A$501,">="&DATE($B$2,8,1),Cobros!$A$2:$A$501,"<"&DATE($B$2,8+1,1)) -> 0 | J13: =SUMIFS(Cobros!$H$2:$H$501,Cobros!$E$2:$E$501,"Efectivo",Cobros!$A$2:$A$501,">="&DATE($B$2,8,1),Cobros!$A$2:$A$501,"<"&DATE($B$2,8+1,1)) -> 0 | K13: =SUMIFS(Cobros!$H$2:$H$501,Cobros!$E$2:$E$501,"Transferencia",Cobros!$A$2:$A$501,">="&DATE($B$2,8,1),Cobros!$A$2:$A$501,"<"&DATE($B$2,8+1,1)) -> 0
A14: Septiembre | B14: =COUNTIFS(Cobros!$A$2:$A$501,">="&DATE($B$2,9,1),Cobros!$A$2:$A$501,"<"&DATE($B$2,9+1,1)) -> 2 | C14: =SUMIFS(Cobros!$F$2:$F$501,Cobros!$A$2:$A$501,">="&DATE($B$2,9,1),Cobros!$A$2:$A$501,"<"&DATE($B$2,9+1,1)) -> 2000 | D14: =SUMIFS(Cobros!$G$2:$G$501,Cobros!$A$2:$A$501,">="&DATE($B$2,9,1),Cobros!$A$2:$A$501,"<"&DATE($B$2,9+1,1)) -> 420 | E14: =SUMIFS(Cobros!$H$2:$H$501,Cobros!$A$2:$A$501,">="&DATE($B$2,9,1),Cobros!$A$2:$A$501,"<"&DATE($B$2,9+1,1)) -> 2420 | F14: =SUMIFS(Cobros!$I$2:$I$501,Cobros!$A$2:$A$501,">="&DATE($B$2,9,1),Cobros!$A$2:$A$501,"<"&DATE($B$2,9+1,1)) -> 300 | G14: =SUMIFS(Cobros!$J$2:$J$501,Cobros!$A$2:$A$501,">="&DATE($B$2,9,1),Cobros!$A$2:$A$501,"<"&DATE($B$2,9+1,1)) -> 1700 | H14: =SUMIFS(Cobros!$K$2:$K$501,Cobros!$A$2:$A$501,">="&DATE($B$2,9,1),Cobros!$A$2:$A$501,"<"&DATE($B$2,9+1,1)) -> 850 | I14: =SUMIFS(Cobros!$L$2:$L$501,Cobros!$A$2:$A$501,">="&DATE($B$2,9,1),Cobros!$A$2:$A$501,"<"&DATE($B$2,9+1,1)) -> 850 | J14: =SUMIFS(Cobros!$H$2:$H$501,Cobros!$E$2:$E$501,"Efectivo",Cobros!$A$2:$A$501,">="&DATE($B$2,9,1),Cobros!$A$2:$A$501,"<"&DATE($B$2,9+1,1)) -> 968 | K14: =SUMIFS(Cobros!$H$2:$H$501,Cobros!$E$2:$E$501,"Transferencia",Cobros!$A$2:$A$501,">="&DATE($B$2,9,1),Cobros!$A$2:$A$501,"<"&DATE($B$2,9+1,1)) -> 1452
A15: Octubre | B15: =COUNTIFS(Cobros!$A$2:$A$501,">="&DATE($B$2,10,1),Cobros!$A$2:$A$501,"<"&DATE($B$2,10+1,1)) -> 3 | C15: =SUMIFS(Cobros!$F$2:$F$501,Cobros!$A$2:$A$501,">="&DATE($B$2,10,1),Cobros!$A$2:$A$501,"<"&DATE($B$2,10+1,1)) -> 3500 | D15: =SUMIFS(Cobros!$G$2:$G$501,Cobros!$A$2:$A$501,">="&DATE($B$2,10,1),Cobros!$A$2:$A$501,"<"&DATE($B$2,10+1,1)) -> 735 | E15: =SUMIFS(Cobros!$H$2:$H$501,Cobros!$A$2:$A$501,">="&DATE($B$2,10,1),Cobros!$A$2:$A$501,"<"&DATE($B$2,10+1,1)) -> 4235 | F15: =SUMIFS(Cobros!$I$2:$I$501,Cobros!$A$2:$A$501,">="&DATE($B$2,10,1),Cobros!$A$2:$A$501,"<"&DATE($B$2,10+1,1)) -> 525 | G15: =SUMIFS(Cobros!$J$2:$J$501,Cobros!$A$2:$A$501,">="&DATE($B$2,10,1),Cobros!$A$2:$A$501,"<"&DATE($B$2,10+1,1)) -> 2975 | H15: =SUMIFS(Cobros!$K$2:$K$501,Cobros!$A$2:$A$501,">="&DATE($B$2,10,1),Cobros!$A$2:$A$501,"<"&DATE($B$2,10+1,1)) -> 1487.5 | I15: =SUMIFS(Cobros!$L$2:$L$501,Cobros!$A$2:$A$501,">="&DATE($B$2,10,1),Cobros!$A$2:$A$501,"<"&DATE($B$2,10+1,1)) -> 1487.5 | J15: =SUMIFS(Cobros!$H$2:$H$501,Cobros!$E$2:$E$501,"Efectivo",Cobros!$A$2:$A$501,">="&DATE($B$2,10,1),Cobros!$A$2:$A$501,"<"&DATE($B$2,10+1,1)) -> 968 | K15: =SUMIFS(Cobros!$H$2:$H$501,Cobros!$E$2:$E$501,"Transferencia",Cobros!$A$2:$A$501,">="&DATE($B$2,10,1),Cobros!$A$2:$A$501,"<"&DATE($B$2,10+1,1)) -> 3267
A16: Noviembre | B16: =COUNTIFS(Cobros!$A$2:$A$501,">="&DATE($B$2,11,1),Cobros!$A$2:$A$501,"<"&DATE($B$2,11+1,1)) -> 0 | C16: =SUMIFS(Cobros!$F$2:$F$501,Cobros!$A$2:$A$501,">="&DATE($B$2,11,1),Cobros!$A$2:$A$501,"<"&DATE($B$2,11+1,1)) -> 0 | D16: =SUMIFS(Cobros!$G$2:$G$501,Cobros!$A$2:$A$501,">="&DATE($B$2,11,1),Cobros!$A$2:$A$501,"<"&DATE($B$2,11+1,1)) -> 0 | E16: =SUMIFS(Cobros!$H$2:$H$501,Cobros!$A$2:$A$501,">="&DATE($B$2,11,1),Cobros!$A$2:$A$501,"<"&DATE($B$2,11+1,1)) -> 0 | F16: =SUMIFS(Cobros!$I$2:$I$501,Cobros!$A$2:$A$501,">="&DATE($B$2,11,1),Cobros!$A$2:$A$501,"<"&DATE($B$2,11+1,1)) -> 0 | G16: =SUMIFS(Cobros!$J$2:$J$501,Cobros!$A$2:$A$501,">="&DATE($B$2,11,1),Cobros!$A$2:$A$501,"<"&DATE($B$2,11+1,1)) -> 0 | H16: =SUMIFS(Cobros!$K$2:$K$501,Cobros!$A$2:$A$501,">="&DATE($B$2,11,1),Cobros!$A$2:$A$501,"<"&DATE($B$2,11+1,1)) -> 0 | I16: =SUMIFS(Cobros!$L$2:$L$501,Cobros!$A$2:$A$501,">="&DATE($B$2,11,1),Cobros!$A$2:$A$501,"<"&DATE($B$2,11+1,1)) -> 0 | J16: =SUMIFS(Cobros!$H$2:$H$501,Cobros!$E$2:$E$501,"Efectivo",Cobros!$A$2:$A$501,">="&DATE($B$2,11,1),Cobros!$A$2:$A$501,"<"&DATE($B$2,11+1,1)) -> 0 | K16: =SUMIFS(Cobros!$H$2:$H$501,Cobros!$E$2:$E$501,"Transferencia",Cobros!$A$2:$A$501,">="&DATE($B$2,11,1),Cobros!$A$2:$A$501,"<"&DATE($B$2,11+1,1)) -> 0
A17: Diciembre | B17: =COUNTIFS(Cobros!$A$2:$A$501,">="&DATE($B$2,12,1),Cobros!$A$2:$A$501,"<"&DATE($B$2,12+1,1)) -> 0 | C17: =SUMIFS(Cobros!$F$2:$F$501,Cobros!$A$2:$A$501,">="&DATE($B$2,12,1),Cobros!$A$2:$A$501,"<"&DATE($B$2,12+1,1)) -> 0 | D17: =SUMIFS(Cobros!$G$2:$G$501,Cobros!$A$2:$A$501,">="&DATE($B$2,12,1),Cobros!$A$2:$A$501,"<"&DATE($B$2,12+1,1)) -> 0 | E17: =SUMIFS(Cobros!$H$2:$H$501,Cobros!$A$2:$A$501,">="&DATE($B$2,12,1),Cobros!$A$2:$A$501,"<"&DATE($B$2,12+1,1)) -> 0 | F17: =SUMIFS(Cobros!$I$2:$I$501,Cobros!$A$2:$A$501,">="&DATE($B$2,12,1),Cobros!$A$2:$A$501,"<"&DATE($B$2,12+1,1)) -> 0 | G17: =SUMIFS(Cobros!$J$2:$J$501,Cobros!$A$2:$A$501,">="&DATE($B$2,12,1),Cobros!$A$2:$A$501,"<"&DATE($B$2,12+1,1)) -> 0 | H17: =SUMIFS(Cobros!$K$2:$K$501,Cobros!$A$2:$A$501,">="&DATE($B$2,12,1),Cobros!$A$2:$A$501,"<"&DATE($B$2,12+1,1)) -> 0 | I17: =SUMIFS(Cobros!$L$2:$L$501,Cobros!$A$2:$A$501,">="&DATE($B$2,12,1),Cobros!$A$2:$A$501,"<"&DATE($B$2,12+1,1)) -> 0 | J17: =SUMIFS(Cobros!$H$2:$H$501,Cobros!$E$2:$E$501,"Efectivo",Cobros!$A$2:$A$501,">="&DATE($B$2,12,1),Cobros!$A$2:$A$501,"<"&DATE($B$2,12+1,1)) -> 0 | K17: =SUMIFS(Cobros!$H$2:$H$501,Cobros!$E$2:$E$501,"Transferencia",Cobros!$A$2:$A$501,">="&DATE($B$2,12,1),Cobros!$A$2:$A$501,"<"&DATE($B$2,12+1,1)) -> 0
A18: Total año | B18: =SUM(B6:B17) -> 5 | C18: =SUM(C6:C17) -> 5500 | D18: =SUM(D6:D17) -> 1155 | E18: =SUM(E6:E17) -> 6655 | F18: =SUM(F6:F17) -> 825 | G18: =SUM(G6:G17) -> 4675 | H18: =SUM(H6:H17) -> 2337.5 | I18: =SUM(I6:I17) -> 2337.5 | ... K18: =SUM(K6:K17) -> 4719
A19: Media mensual | C19: =IF(COUNTIF($B$6:$B$17,">0")=0,0,C18/COUNTIF($B$6:$B$17,">0")) -> 2750 | D19: =IF(COUNTIF($B$6:$B$17,">0")=0,0,D18/COUNTIF($B$6:$B$17,">0")) -> 577.5 | E19: =IF(COUNTIF($B$6:$B$17,">0")=0,0,E18/COUNTIF($B$6:$B$17,">0")) -> 3327.5 | F19: =IF(COUNTIF($B$6:$B$17,">0")=0,0,F18/COUNTIF($B$6:$B$17,">0")) -> 412.5 | G19: =IF(COUNTIF($B$6:$B$17,">0")=0,0,G18/COUNTIF($B$6:$B$17,">0")) -> 2337.5 | H19: =IF(COUNTIF($B$6:$B$17,">0")=0,0,H18/COUNTIF($B$6:$B$17,">0")) -> 1168.75 | I19: =IF(COUNTIF($B$6:$B$17,">0")=0,0,I18/COUNTIF($B$6:$B$17,">0")) -> 1168.75 | J19: =IF(COUNTIF($B$6:$B$17,">0")=0,0,J18/COUNTIF($B$6:$B$17,">0")) -> 968 | K19: =IF(COUNTIF($B$6:$B$17,">0")=0,0,K18/COUNTIF($B$6:$B$17,">0")) -> 2359.5
A20: La media solo cuenta los meses con algún cobro.
A22: Por trimestres
A23: Trimestre | B23: Nº cobros | C23: Base imponible (€) | D23: IVA cobrado (€) | E23: Total con IVA (€) | F23: IRPF (€) | G23: Neto (€) | H23: ="Neto "&Configuración!$B$4&" (€)" -> Neto Socia 1 (€) | I23: ="Neto "&Configuración!$B$5&" (€)" -> Neto Socia 2 (€)
A24: 1T (Ene–Mar) | B24: =SUM(B6:B8) -> 0 | C24: =SUM(C6:C8) -> 0 | D24: =SUM(D6:D8) -> 0 | E24: =SUM(E6:E8) -> 0 | F24: =SUM(F6:F8) -> 0 | G24: =SUM(G6:G8) -> 0 | H24: =SUM(H6:H8) -> 0 | I24: =SUM(I6:I8) -> 0
A25: 2T (Abr–Jun) | B25: =SUM(B9:B11) -> 0 | C25: =SUM(C9:C11) -> 0 | D25: =SUM(D9:D11) -> 0 | E25: =SUM(E9:E11) -> 0 | F25: =SUM(F9:F11) -> 0 | G25: =SUM(G9:G11) -> 0 | H25: =SUM(H9:H11) -> 0 | I25: =SUM(I9:I11) -> 0
A26: 3T (Jul–Sep) | B26: =SUM(B12:B14) -> 2 | C26: =SUM(C12:C14) -> 2000 | D26: =SUM(D12:D14) -> 420 | E26: =SUM(E12:E14) -> 2420 | F26: =SUM(F12:F14) -> 300 | G26: =SUM(G12:G14) -> 1700 | H26: =SUM(H12:H14) -> 850 | I26: =SUM(I12:I14) -> 850
A27: 4T (Oct–Dic) | B27: =SUM(B15:B17) -> 3 | C27: =SUM(C15:C17) -> 3500 | D27: =SUM(D15:D17) -> 735 | E27: =SUM(E15:E17) -> 4235 | F27: =SUM(F15:F17) -> 525 | G27: =SUM(G15:G17) -> 2975 | H27: =SUM(H15:H17) -> 1487.5 | I27: =SUM(I15:I17) -> 1487.5
A29: IVA cobrado = el que tendrás que ingresar en el modelo 303, menos el IVA de tus facturas de gastos (este libro no registra gastos).

Sheet Detalle del mes
A1: Detalle del mes
A3: Año | B3: =Configuración!$B$13 -> 2026 | C3: ← puedes escribir otro año si quieres
A4: Mes (1-12) | B4: 10 | C4: =INDEX({"Enero","Febrero","Marzo","Abril","Mayo","Junio","Julio","Agosto","Septiembre","Octubre","Noviembre","Diciembre"},B4) -> Octubre
A6: Concepto | B6: Total agencia (€) | C6: =Configuración!$B$4&" (€)" -> Socia 1 (€) | D6: =Configuración!$B$5&" (€)" -> Socia 2 (€)
A7: Facturado (base imponible) | B7: =SUMIFS(Cobros!$F$2:$F$501,Cobros!$A$2:$A$501,">="&DATE($B$3,$B$4,1),Cobros!$A$2:$A$501,"<"&DATE($B$3,$B$4+1,1)) -> 3500 | C7: =B7*Configuración!$C$4 -> 1750 | D7: =B7*Configuración!$C$5 -> 1750
A8: IVA (para Hacienda) | B8: =SUMIFS(Cobros!$G$2:$G$501,Cobros!$A$2:$A$501,">="&DATE($B$3,$B$4,1),Cobros!$A$2:$A$501,"<"&DATE($B$3,$B$4+1,1)) -> 735 | C8: =B8*Configuración!$C$4 -> 367.5 | D8: =B8*Configuración!$C$5 -> 367.5
A9: Total cobrado con IVA | B9: =SUMIFS(Cobros!$H$2:$H$501,Cobros!$A$2:$A$501,">="&DATE($B$3,$B$4,1),Cobros!$A$2:$A$501,"<"&DATE($B$3,$B$4+1,1)) -> 4235 | C9: =B9*Configuración!$C$4 -> 2117.5 | D9: =B9*Configuración!$C$5 -> 2117.5
A10: IRPF a apartar | B10: =SUMIFS(Cobros!$I$2:$I$501,Cobros!$A$2:$A$501,">="&DATE($B$3,$B$4,1),Cobros!$A$2:$A$501,"<"&DATE($B$3,$B$4+1,1)) -> 525 | C10: =B10*Configuración!$C$4 -> 262.5 | D10: =B10*Configuración!$C$5 -> 262.5
A11: Neto (lo que ganáis) | B11: =SUMIFS(Cobros!$J$2:$J$501,Cobros!$A$2:$A$501,">="&DATE($B$3,$B$4,1),Cobros!$A$2:$A$501,"<"&DATE($B$3,$B$4+1,1)) -> 2975 | C11: =B11*Configuración!$C$4 -> 1487.5 | D11: =B11*Configuración!$C$5 -> 1487.5
A13: Cobrado en efectivo (con IVA) | B13: =SUMIFS(Cobros!$H$2:$H$501,Cobros!$E$2:$E$501,"Efectivo",Cobros!$A$2:$A$501,">="&DATE($B$3,$B$4,1),Cobros!$A$2:$A$501,"<"&DATE($B$3,$B$4+1,1)) -> 968
A14: Cobrado por transferencia (con IVA) | B14: =SUMIFS(Cobros!$H$2:$H$501,Cobros!$E$2:$E$501,"Transferencia",Cobros!$A$2:$A$501,">="&DATE($B$3,$B$4,1),Cobros!$A$2:$A$501,"<"&DATE($B$3,$B$4+1,1)) -> 3267
A15: Número de cobros | B15: =COUNTIFS(Cobros!$A$2:$A$501,">="&DATE($B$3,$B$4,1),Cobros!$A$2:$A$501,"<"&DATE($B$3,$B$4+1,1)) -> 3
A17: Cliente | B17: Base imponible (€) | C17: IVA (€) | D17: Total con IVA (€) | E17: IRPF (€) | F17: Neto (€) | G17: Forma de pago: efectivo (€) | H17: Forma de pago: transferencia (€)
A18: =IF(Configuración!A16="","",Configuración!A16) -> Cliente A (ejemplo) | B18: =IF($A18="","",SUMIFS(Cobros!$F$2:$F$501,Cobros!$B$2:$B$501,$A18,Cobros!$A$2:$A$501,">="&DATE($B$3,$B$4,1),Cobros!$A$2:$A$501,"<"&DATE($B$3,$B$4+1,1))) -> 1200 | C18: =IF($A18="","",SUMIFS(Cobros!$G$2:$G$501,Cobros!$B$2:$B$501,$A18,Cobros!$A$2:$A$501,">="&DATE($B$3,$B$4,1),Cobros!$A$2:$A$501,"<"&DATE($B$3,$B$4+1,1))) -> 252 | D18: =IF($A18="","",SUMIFS(Cobros!$H$2:$H$501,Cobros!$B$2:$B$501,$A18,Cobros!$A$2:$A$501,">="&DATE($B$3,$B$4,1),Cobros!$A$2:$A$501,"<"&DATE($B$3,$B$4+1,1))) -> 1452 | E18: =IF($A18="","",SUMIFS(Cobros!$I$2:$I$501,Cobros!$B$2:$B$501,$A18,Cobros!$A$2:$A$501,">="&DATE($B$3,$B$4,1),Cobros!$A$2:$A$501,"<"&DATE($B$3,$B$4+1,1))) -> 180 | F18: =IF($A18="","",SUMIFS(Cobros!$J$2:$J$501,Cobros!$B$2:$B$501,$A18,Cobros!$A$2:$A$501,">="&DATE($B$3,$B$4,1),Cobros!$A$2:$A$501,"<"&DATE($B$3,$B$4+1,1))) -> 1020 | G18: =IF($A18="","",SUMIFS(Cobros!$H$2:$H$501,Cobros!$B$2:$B$501,$A18,Cobros!$E$2:$E$501,"Efectivo",Cobros!$A$2:$A$501,">="&DATE($B$3,$B$4,1),Cobros!$A$2:$A$501,"<"&DATE($B$3,$B$4+1,1))) -> 0 | H18: =IF($A18="","",SUMIFS(Cobros!$H$2:$H$501,Cobros!$B$2:$B$501,$A18,Cobros!$E$2:$E$501,"Transferencia",Cobros!$A$2:$A$501,">="&DATE($B$3,$B$4,1),Cobros!$A$2:$A$501,"<"&DATE($B$3,$B$4+1,1))) -> 1452
A19: =IF(Configuración!A17="","",Configuración!A17) -> Cliente B (ejemplo) | B19: =IF($A19="","",SUMIFS(Cobros!$F$2:$F$501,Cobros!$B$2:$B$501,$A19,Cobros!$A$2:$A$501,">="&DATE($B$3,$B$4,1),Cobros!$A$2:$A$501,"<"&DATE($B$3,$B$4+1,1))) -> 800 | C19: =IF($A19="","",SUMIFS(Cobros!$G$2:$G$501,Cobros!$B$2:$B$501,$A19,Cobros!$A$2:$A$501,">="&DATE($B$3,$B$4,1),Cobros!$A$2:$A$501,"<"&DATE($B$3,$B$4+1,1))) -> 168 | D19: =IF($A19="","",SUMIFS(Cobros!$H$2:$H$501,Cobros!$B$2:$B$501,$A19,Cobros!$A$2:$A$501,">="&DATE($B$3,$B$4,1),Cobros!$A$2:$A$501,"<"&DATE($B$3,$B$4+1,1))) -> 968 | E19: =IF($A19="","",SUMIFS(Cobros!$I$2:$I$501,Cobros!$B$2:$B$501,$A19,Cobros!$A$2:$A$501,">="&DATE($B$3,$B$4,1),Cobros!$A$2:$A$501,"<"&DATE($B$3,$B$4+1,1))) -> 120 | F19: =IF($A19="","",SUMIFS(Cobros!$J$2:$J$501,Cobros!$B$2:$B$501,$A19,Cobros!$A$2:$A$501,">="&DATE($B$3,$B$4,1),Cobros!$A$2:$A$501,"<"&DATE($B$3,$B$4+1,1))) -> 680 | G19: =IF($A19="","",SUMIFS(Cobros!$H$2:$H$501,Cobros!$B$2:$B$501,$A19,Cobros!$E$2:$E$501,"Efectivo",Cobros!$A$2:$A$501,">="&DATE($B$3,$B$4,1),Cobros!$A$2:$A$501,"<"&DATE($B$3,$B$4+1,1))) -> 968 | H19: =IF($A19="","",SUMIFS(Cobros!$H$2:$H$501,Cobros!$B$2:$B$501,$A19,Cobros!$E$2:$E$501,"Transferencia",Cobros!$A$2:$A$501,">="&DATE($B$3,$B$4,1),Cobros!$A$2:$A$501,"<"&DATE($B$3,$B$4+1,1))) -> 0
A20: =IF(Configuración!A18="","",Configuración!A18) -> Cliente C (ejemplo) | B20: =IF($A20="","",SUMIFS(Cobros!$F$2:$F$501,Cobros!$B$2:$B$501,$A20,Cobros!$A$2:$A$501,">="&DATE($B$3,$B$4,1),Cobros!$A$2:$A$501,"<"&DATE($B$3,$B$4+1,1))) -> 1500 | C20: =IF($A20="","",SUMIFS(Cobros!$G$2:$G$501,Cobros!$B$2:$B$501,$A20,Cobros!$A$2:$A$501,">="&DATE($B$3,$B$4,1),Cobros!$A$2:$A$501,"<"&DATE($B$3,$B$4+1,1))) -> 315 | D20: =IF($A20="","",SUMIFS(Cobros!$H$2:$H$501,Cobros!$B$2:$B$501,$A20,Cobros!$A$2:$A$501,">="&DATE($B$3,$B$4,1),Cobros!$A$2:$A$501,"<"&DATE($B$3,$B$4+1,1))) -> 1815 | E20: =IF($A20="","",SUMIFS(Cobros!$I$2:$I$501,Cobros!$B$2:$B$501,$A20,Cobros!$A$2:$A$501,">="&DATE($B$3,$B$4,1),Cobros!$A$2:$A$501,"<"&DATE($B$3,$B$4+1,1))) -> 225 | F20: =IF($A20="","",SUMIFS(Cobros!$J$2:$J$501,Cobros!$B$2:$B$501,$A20,Cobros!$A$2:$A$501,">="&DATE($B$3,$B$4,1),Cobros!$A$2:$A$501,"<"&DATE($B$3,$B$4+1,1))) -> 1275 | G20: =IF($A20="","",SUMIFS(Cobros!$H$2:$H$501,Cobros!$B$2:$B$501,$A20,Cobros!$E$2:$E$501,"Efectivo",Cobros!$A$2:$A$501,">="&DATE($B$3,$B$4,1),Cobros!$A$2:$A$501,"<"&DATE($B$3,$B$4+1,1))) -> 0 | H20: =IF($A20="","",SUMIFS(Cobros!$H$2:$H$501,Cobros!$B$2:$B$501,$A20,Cobros!$E$2:$E$501,"Transferencia",Cobros!$A$2:$A$501,">="&DATE($B$3,$B$4,1),Cobros!$A$2:$A$501,"<"&DATE($B$3,$B$4+1,1))) -> 1815
A21: =IF(Configuración!A19="","",Configuración!A19) -> Cliente D (ejemplo) | B21: =IF($A21="","",SUMIFS(Cobros!$F$2:$F$501,Cobros!$B$2:$B$501,$A21,Cobros!$A$2:$A$501,">="&DATE($B$3,$B$4,1),Cobros!$A$2:$A$501,"<"&DATE($B$3,$B$4+1,1))) -> 0 | C21: =IF($A21="","",SUMIFS(Cobros!$G$2:$G$501,Cobros!$B$2:$B$501,$A21,Cobros!$A$2:$A$501,">="&DATE($B$3,$B$4,1),Cobros!$A$2:$A$501,"<"&DATE($B$3,$B$4+1,1))) -> 0 | D21: =IF($A21="","",SUMIFS(Cobros!$H$2:$H$501,Cobros!$B$2:$B$501,$A21,Cobros!$A$2:$A$501,">="&DATE($B$3,$B$4,1),Cobros!$A$2:$A$501,"<"&DATE($B$3,$B$4+1,1))) -> 0 | E21: =IF($A21="","",SUMIFS(Cobros!$I$2:$I$501,Cobros!$B$2:$B$501,$A21,Cobros!$A$2:$A$501,">="&DATE($B$3,$B$4,1),Cobros!$A$2:$A$501,"<"&DATE($B$3,$B$4+1,1))) -> 0 | F21: =IF($A21="","",SUMIFS(Cobros!$J$2:$J$501,Cobros!$B$2:$B$501,$A21,Cobros!$A$2:$A$501,">="&DATE($B$3,$B$4,1),Cobros!$A$2:$A$501,"<"&DATE($B$3,$B$4+1,1))) -> 0 | G21: =IF($A21="","",SUMIFS(Cobros!$H$2:$H$501,Cobros!$B$2:$B$501,$A21,Cobros!$E$2:$E$501,"Efectivo",Cobros!$A$2:$A$501,">="&DATE($B$3,$B$4,1),Cobros!$A$2:$A$501,"<"&DATE($B$3,$B$4+1,1))) -> 0 | H21: =IF($A21="","",SUMIFS(Cobros!$H$2:$H$501,Cobros!$B$2:$B$501,$A21,Cobros!$E$2:$E$501,"Transferencia",Cobros!$A$2:$A$501,">="&DATE($B$3,$B$4,1),Cobros!$A$2:$A$501,"<"&DATE($B$3,$B$4+1,1))) -> 0
A22: =IF(Configuración!A20="","",Configuración!A20) | B22: =IF($A22="","",SUMIFS(Cobros!$F$2:$F$501,Cobros!$B$2:$B$501,$A22,Cobros!$A$2:$A$501,">="&DATE($B$3,$B$4,1),Cobros!$A$2:$A$501,"<"&DATE($B$3,$B$4+1,1))) | C22: =IF($A22="","",SUMIFS(Cobros!$G$2:$G$501,Cobros!$B$2:$B$501,$A22,Cobros!$A$2:$A$501,">="&DATE($B$3,$B$4,1),Cobros!$A$2:$A$501,"<"&DATE($B$3,$B$4+1,1))) | D22: =IF($A22="","",SUMIFS(Cobros!$H$2:$H$501,Cobros!$B$2:$B$501,$A22,Cobros!$A$2:$A$501,">="&DATE($B$3,$B$4,1),Cobros!$A$2:$A$501,"<"&DATE($B$3,$B$4+1,1))) | E22: =IF($A22="","",SUMIFS(Cobros!$I$2:$I$501,Cobros!$B$2:$B$501,$A22,Cobros!$A$2:$A$501,">="&DATE($B$3,$B$4,1),Cobros!$A$2:$A$501,"<"&DATE($B$3,$B$4+1,1))) | F22: =IF($A22="","",SUMIFS(Cobros!$J$2:$J$501,Cobros!$B$2:$B$501,$A22,Cobros!$A$2:$A$501,">="&DATE($B$3,$B$4,1),Cobros!$A$2:$A$501,"<"&DATE($B$3,$B$4+1,1))) | G22: =IF($A22="","",SUMIFS(Cobros!$H$2:$H$501,Cobros!$B$2:$B$501,$A22,Cobros!$E$2:$E$501,"Efectivo",Cobros!$A$2:$A$501,">="&DATE($B$3,$B$4,1),Cobros!$A$2:$A$501,"<"&DATE($B$3,$B$4+1,1))) | H22: =IF($A22="","",SUMIFS(Cobros!$H$2:$H$501,Cobros!$B$2:$B$501,$A22,Cobros!$E$2:$E$501,"Transferencia",Cobros!$A$2:$A$501,">="&DATE($B$3,$B$4,1),Cobros!$A$2:$A$501,"<"&DATE($B$3,$B$4+1,1)))
A23: =IF(Configuración!A21="","",Configuración!A21) | B23: =IF($A23="","",SUMIFS(Cobros!$F$2:$F$501,Cobros!$B$2:$B$501,$A23,Cobros!$A$2:$A$501,">="&DATE($B$3,$B$4,1),Cobros!$A$2:$A$501,"<"&DATE($B$3,$B$4+1,1))) | C23: =IF($A23="","",SUMIFS(Cobros!$G$2:$G$501,Cobros!$B$2:$B$501,$A23,Cobros!$A$2:$A$501,">="&DATE($B$3,$B$4,1),Cobros!$A$2:$A$501,"<"&DATE($B$3,$B$4+1,1))) | D23: =IF($A23="","",SUMIFS(Cobros!$H$2:$H$501,Cobros!$B$2:$B$501,$A23,Cobros!$A$2:$A$501,">="&DATE($B$3,$B$4,1),Cobros!$A$2:$A$501,"<"&DATE($B$3,$B$4+1,1))) | E23: =IF($A23="","",SUMIFS(Cobros!$I$2:$I$501,Cobros!$B$2:$B$501,$A23,Cobros!$A$2:$A$501,">="&DATE($B$3,$B$4,1),Cobros!$A$2:$A$501,"<"&DATE($B$3,$B$4+1,1))) | F23: =IF($A23="","",SUMIFS(Cobros!$J$2:$J$501,Cobros!$B$2:$B$501,$A23,Cobros!$A$2:$A$501,">="&DATE($B$3,$B$4,1),Cobros!$A$2:$A$501,"<"&DATE($B$3,$B$4+1,1))) | G23: =IF($A23="","",SUMIFS(Cobros!$H$2:$H$501,Cobros!$B$2:$B$501,$A23,Cobros!$E$2:$E$501,"Efectivo",Cobros!$A$2:$A$501,">="&DATE($B$3,$B$4,1),Cobros!$A$2:$A$501,"<"&DATE($B$3,$B$4+1,1))) | H23: =IF($A23="","",SUMIFS(Cobros!$H$2:$H$501,Cobros!$B$2:$B$501,$A23,Cobros!$E$2:$E$501,"Transferencia",Cobros!$A$2:$A$501,">="&DATE($B$3,$B$4,1),Cobros!$A$2:$A$501,"<"&DATE($B$3,$B$4+1,1)))
A24: =IF(Configuración!A22="","",Configuración!A22) | B24: =IF($A24="","",SUMIFS(Cobros!$F$2:$F$501,Cobros!$B$2:$B$501,$A24,Cobros!$A$2:$A$501,">="&DATE($B$3,$B$4,1),Cobros!$A$2:$A$501,"<"&DATE($B$3,$B$4+1,1))) | C24: =IF($A24="","",SUMIFS(Cobros!$G$2:$G$501,Cobros!$B$2:$B$501,$A24,Cobros!$A$2:$A$501,">="&DATE($B$3,$B$4,1),Cobros!$A$2:$A$501,"<"&DATE($B$3,$B$4+1,1))) | D24: =IF($A24="","",SUMIFS(Cobros!$H$2:$H$501,Cobros!$B$2:$B$501,$A24,Cobros!$A$2:$A$501,">="&DATE($B$3,$B$4,1),Cobros!$A$2:$A$501,"<"&DATE($B$3,$B$4+1,1))) | E24: =IF($A24="","",SUMIFS(Cobros!$I$2:$I$501,Cobros!$B$2:$B$501,$A24,Cobros!$A$2:$A$501,">="&DATE($B$3,$B$4,1),Cobros!$A$2:$A$501,"<"&DATE($B$3,$B$4+1,1))) | F24: =IF($A24="","",SUMIFS(Cobros!$J$2:$J$501,Cobros!$B$2:$B$501,$A24,Cobros!$A$2:$A$501,">="&DATE($B$3,$B$4,1),Cobros!$A$2:$A$501,"<"&DATE($B$3,$B$4+1,1))) | G24: =IF($A24="","",SUMIFS(Cobros!$H$2:$H$501,Cobros!$B$2:$B$501,$A24,Cobros!$E$2:$E$501,"Efectivo",Cobros!$A$2:$A$501,">="&DATE($B$3,$B$4,1),Cobros!$A$2:$A$501,"<"&DATE($B$3,$B$4+1,1))) | H24: =IF($A24="","",SUMIFS(Cobros!$H$2:$H$501,Cobros!$B$2:$B$501,$A24,Cobros!$E$2:$E$501,"Transferencia",Cobros!$A$2:$A$501,">="&DATE($B$3,$B$4,1),Cobros!$A$2:$A$501,"<"&DATE($B$3,$B$4+1,1)))
A25: =IF(Configuración!A23="","",Configuración!A23) | B25: =IF($A25="","",SUMIFS(Cobros!$F$2:$F$501,Cobros!$B$2:$B$501,$A25,Cobros!$A$2:$A$501,">="&DATE($B$3,$B$4,1),Cobros!$A$2:$A$501,"<"&DATE($B$3,$B$4+1,1))) | C25: =IF($A25="","",SUMIFS(Cobros!$G$2:$G$501,Cobros!$B$2:$B$501,$A25,Cobros!$A$2:$A$501,">="&DATE($B$3,$B$4,1),Cobros!$A$2:$A$501,"<"&DATE($B$3,$B$4+1,1))) | D25: =IF($A25="","",SUMIFS(Cobros!$H$2:$H$501,Cobros!$B$2:$B$501,$A25,Cobros!$A$2:$A$501,">="&DATE($B$3,$B$4,1),Cobros!$A$2:$A$501,"<"&DATE($B$3,$B$4+1,1))) | E25: =IF($A25="","",SUMIFS(Cobros!$I$2:$I$501,Cobros!$B$2:$B$501,$A25,Cobros!$A$2:$A$501,">="&DATE($B$3,$B$4,1),Cobros!$A$2:$A$501,"<"&DATE($B$3,$B$4+1,1))) | F25: =IF($A25="","",SUMIFS(Cobros!$J$2:$J$501,Cobros!$B$2:$B$501,$A25,Cobros!$A$2:$A$501,">="&DATE($B$3,$B$4,1),Cobros!$A$2:$A$501,"<"&DATE($B$3,$B$4+1,1))) | G25: =IF($A25="","",SUMIFS(Cobros!$H$2:$H$501,Cobros!$B$2:$B$501,$A25,Cobros!$E$2:$E$501,"Efectivo",Cobros!$A$2:$A$501,">="&DATE($B$3,$B$4,1),Cobros!$A$2:$A$501,"<"&DATE($B$3,$B$4+1,1))) | H25: =IF($A25="","",SUMIFS(Cobros!$H$2:$H$501,Cobros!$B$2:$B$501,$A25,Cobros!$E$2:$E$501,"Transferencia",Cobros!$A$2:$A$501,">="&DATE($B$3,$B$4,1),Cobros!$A$2:$A$501,"<"&DATE($B$3,$B$4+1,1)))
A26: =IF(Configuración!A24="","",Configuración!A24) | B26: =IF($A26="","",SUMIFS(Cobros!$F$2:$F$501,Cobros!$B$2:$B$501,$A26,Cobros!$A$2:$A$501,">="&DATE($B$3,$B$4,1),Cobros!$A$2:$A$501,"<"&DATE($B$3,$B$4+1,1))) | C26: =IF($A26="","",SUMIFS(Cobros!$G$2:$G$501,Cobros!$B$2:$B$501,$A26,Cobros!$A$2:$A$501,">="&DATE($B$3,$B$4,1),Cobros!$A$2:$A$501,"<"&DATE($B$3,$B$4+1,1))) | D26: =IF($A26="","",SUMIFS(Cobros!$H$2:$H$501,Cobros!$B$2:$B$501,$A26,Cobros!$A$2:$A$501,">="&DATE($B$3,$B$4,1),Cobros!$A$2:$A$501,"<"&DATE($B$3,$B$4+1,1))) | E26: =IF($A26="","",SUMIFS(Cobros!$I$2:$I$501,Cobros!$B$2:$B$501,$A26,Cobros!$A$2:$A$501,">="&DATE($B$3,$B$4,1),Cobros!$A$2:$A$501,"<"&DATE($B$3,$B$4+1,1))) | F26: =IF($A26="","",SUMIFS(Cobros!$J$2:$J$501,Cobros!$B$2:$B$501,$A26,Cobros!$A$2:$A$501,">="&DATE($B$3,$B$4,1),Cobros!$A$2:$A$501,"<"&DATE($B$3,$B$4+1,1))) | G26: =IF($A26="","",SUMIFS(Cobros!$H$2:$H$501,Cobros!$B$2:$B$501,$A26,Cobros!$E$2:$E$501,"Efectivo",Cobros!$A$2:$A$501,">="&DATE($B$3,$B$4,1),Cobros!$A$2:$A$501,"<"&DATE($B$3,$B$4+1,1))) | H26: =IF($A26="","",SUMIFS(Cobros!$H$2:$H$501,Cobros!$B$2:$B$501,$A26,Cobros!$E$2:$E$501,"Transferencia",Cobros!$A$2:$A$501,">="&DATE($B$3,$B$4,1),Cobros!$A$2:$A$501,"<"&DATE($B$3,$B$4+1,1)))
A27: =IF(Configuración!A25="","",Configuración!A25) | B27: =IF($A27="","",SUMIFS(Cobros!$F$2:$F$501,Cobros!$B$2:$B$501,$A27,Cobros!$A$2:$A$501,">="&DATE($B$3,$B$4,1),Cobros!$A$2:$A$501,"<"&DATE($B$3,$B$4+1,1))) | C27: =IF($A27="","",SUMIFS(Cobros!$G$2:$G$501,Cobros!$B$2:$B$501,$A27,Cobros!$A$2:$A$501,">="&DATE($B$3,$B$4,1),Cobros!$A$2:$A$501,"<"&DATE($B$3,$B$4+1,1))) | D27: =IF($A27="","",SUMIFS(Cobros!$H$2:$H$501,Cobros!$B$2:$B$501,$A27,Cobros!$A$2:$A$501,">="&DATE($B$3,$B$4,1),Cobros!$A$2:$A$501,"<"&DATE($B$3,$B$4+1,1))) | E27: =IF($A27="","",SUMIFS(Cobros!$I$2:$I$501,Cobros!$B$2:$B$501,$A27,Cobros!$A$2:$A$501,">="&DATE($B$3,$B$4,1),Cobros!$A$2:$A$501,"<"&DATE($B$3,$B$4+1,1))) | F27: =IF($A27="","",SUMIFS(Cobros!$J$2:$J$501,Cobros!$B$2:$B$501,$A27,Cobros!$A$2:$A$501,">="&DATE($B$3,$B$4,1),Cobros!$A$2:$A$501,"<"&DATE($B$3,$B$4+1,1))) | G27: =IF($A27="","",SUMIFS(Cobros!$H$2:$H$501,Cobros!$B$2:$B$501,$A27,Cobros!$E$2:$E$501,"Efectivo",Cobros!$A$2:$A$501,">="&DATE($B$3,$B$4,1),Cobros!$A$2:$A$501,"<"&DATE($B$3,$B$4+1,1))) | H27: =IF($A27="","",SUMIFS(Cobros!$H$2:$H$501,Cobros!$B$2:$B$501,$A27,Cobros!$E$2:$E$501,"Transferencia",Cobros!$A$2:$A$501,">="&DATE($B$3,$B$4,1),Cobros!$A$2:$A$501,"<"&DATE($B$3,$B$4+1,1)))
A28: =IF(Configuración!A26="","",Configuración!A26) | B28: =IF($A28="","",SUMIFS(Cobros!$F$2:$F$501,Cobros!$B$2:$B$501,$A28,Cobros!$A$2:$A$501,">="&DATE($B$3,$B$4,1),Cobros!$A$2:$A$501,"<"&DATE($B$3,$B$4+1,1))) | C28: =IF($A28="","",SUMIFS(Cobros!$G$2:$G$501,Cobros!$B$2:$B$501,$A28,Cobros!$A$2:$A$501,">="&DATE($B$3,$B$4,1),Cobros!$A$2:$A$501,"<"&DATE($B$3,$B$4+1,1))) | D28: =IF($A28="","",SUMIFS(Cobros!$H$2:$H$501,Cobros!$B$2:$B$501,$A28,Cobros!$A$2:$A$501,">="&DATE($B$3,$B$4,1),Cobros!$A$2:$A$501,"<"&DATE($B$3,$B$4+1,1))) | E28: =IF($A28="","",SUMIFS(Cobros!$I$2:$I$501,Cobros!$B$2:$B$501,$A28,Cobros!$A$2:$A$501,">="&DATE($B$3,$B$4,1),Cobros!$A$2:$A$501,"<"&DATE($B$3,$B$4+1,1))) | F28: =IF($A28="","",SUMIFS(Cobros!$J$2:$J$501,Cobros!$B$2:$B$501,$A28,Cobros!$A$2:$A$501,">="&DATE($B$3,$B$4,1),Cobros!$A$2:$A$501,"<"&DATE($B$3,$B$4+1,1))) | G28: =IF($A28="","",SUMIFS(Cobros!$H$2:$H$501,Cobros!$B$2:$B$501,$A28,Cobros!$E$2:$E$501,"Efectivo",Cobros!$A$2:$A$501,">="&DATE($B$3,$B$4,1),Cobros!$A$2:$A$501,"<"&DATE($B$3,$B$4+1,1))) | H28: =IF($A28="","",SUMIFS(Cobros!$H$2:$H$501,Cobros!$B$2:$B$501,$A28,Cobros!$E$2:$E$501,"Transferencia",Cobros!$A$2:$A$501,">="&DATE($B$3,$B$4,1),Cobros!$A$2:$A$501,"<"&DATE($B$3,$B$4+1,1)))
A29: =IF(Configuración!A27="","",Configuración!A27) | B29: =IF($A29="","",SUMIFS(Cobros!$F$2:$F$501,Cobros!$B$2:$B$501,$A29,Cobros!$A$2:$A$501,">="&DATE($B$3,$B$4,1),Cobros!$A$2:$A$501,"<"&DATE($B$3,$B$4+1,1))) | C29: =IF($A29="","",SUMIFS(Cobros!$G$2:$G$501,Cobros!$B$2:$B$501,$A29,Cobros!$A$2:$A$501,">="&DATE($B$3,$B$4,1),Cobros!$A$2:$A$501,"<"&DATE($B$3,$B$4+1,1))) | D29: =IF($A29="","",SUMIFS(Cobros!$H$2:$H$501,Cobros!$B$2:$B$501,$A29,Cobros!$A$2:$A$501,">="&DATE($B$3,$B$4,1),Cobros!$A$2:$A$501,"<"&DATE($B$3,$B$4+1,1))) | E29: =IF($A29="","",SUMIFS(Cobros!$I$2:$I$501,Cobros!$B$2:$B$501,$A29,Cobros!$A$2:$A$501,">="&DATE($B$3,$B$4,1),Cobros!$A$2:$A$501,"<"&DATE($B$3,$B$4+1,1))) | F29: =IF($A29="","",SUMIFS(Cobros!$J$2:$J$501,Cobros!$B$2:$B$501,$A29,Cobros!$A$2:$A$501,">="&DATE($B$3,$B$4,1),Cobros!$A$2:$A$501,"<"&DATE($B$3,$B$4+1,1))) | G29: =IF($A29="","",SUMIFS(Cobros!$H$2:$H$501,Cobros!$B$2:$B$501,$A29,Cobros!$E$2:$E$501,"Efectivo",Cobros!$A$2:$A$501,">="&DATE($B$3,$B$4,1),Cobros!$A$2:$A$501,"<"&DATE($B$3,$B$4+1,1))) | H29: =IF($A29="","",SUMIFS(Cobros!$H$2:$H$501,Cobros!$B$2:$B$501,$A29,Cobros!$E$2:$E$501,"Transferencia",Cobros!$A$2:$A$501,">="&DATE($B$3,$B$4,1),Cobros!$A$2:$A$501,"<"&DATE($B$3,$B$4+1,1)))
... A47: =IF(Configuración!A45="","",Configuración!A45) | B47: =IF($A47="","",SUMIFS(Cobros!$F$2:$F$501,Cobros!$B$2:$B$501,$A47,Cobros!$A$2:$A$501,">="&DATE($B$3,$B$4,1),Cobros!$A$2:$A$501,"<"&DATE($B$3,$B$4+1,1))) | C47: =IF($A47="","",SUMIFS(Cobros!$G$2:$G$501,Cobros!$B$2:$B$501,$A47,Cobros!$A$2:$A$501,">="&DATE($B$3,$B$4,1),Cobros!$A$2:$A$501,"<"&DATE($B$3,$B$4+1,1))) | D47: =IF($A47="","",SUMIFS(Cobros!$H$2:$H$501,Cobros!$B$2:$B$501,$A47,Cobros!$A$2:$A$501,">="&DATE($B$3,$B$4,1),Cobros!$A$2:$A$501,"<"&DATE($B$3,$B$4+1,1))) | E47: =IF($A47="","",SUMIFS(Cobros!$I$2:$I$501,Cobros!$B$2:$B$501,$A47,Cobros!$A$2:$A$501,">="&DATE($B$3,$B$4,1),Cobros!$A$2:$A$501,"<"&DATE($B$3,$B$4+1,1))) | F47: =IF($A47="","",SUMIFS(Cobros!$J$2:$J$501,Cobros!$B$2:$B$501,$A47,Cobros!$A$2:$A$501,">="&DATE($B$3,$B$4,1),Cobros!$A$2:$A$501,"<"&DATE($B$3,$B$4+1,1))) | G47: =IF($A47="","",SUMIFS(Cobros!$H$2:$H$501,Cobros!$B$2:$B$501,$A47,Cobros!$E$2:$E$501,"Efectivo",Cobros!$A$2:$A$501,">="&DATE($B$3,$B$4,1),Cobros!$A$2:$A$501,"<"&DATE($B$3,$B$4+1,1))) | H47: =IF($A47="","",SUMIFS(Cobros!$H$2:$H$501,Cobros!$B$2:$B$501,$A47,Cobros!$E$2:$E$501,"Transferencia",Cobros!$A$2:$A$501,">="&DATE($B$3,$B$4,1),Cobros!$A$2:$A$501,"<"&DATE($B$3,$B$4+1,1)))
A48: Total | B48: =SUM(B18:B47) -> 3500 | C48: =SUM(C18:C47) -> 735 | D48: =SUM(D18:D47) -> 4235 | E48: =SUM(E18:E47) -> 525 | F48: =SUM(F18:F47) -> 2975 | G48: =SUM(G18:G47) -> 968 | H48: =SUM(H18:H47) -> 3267

Sheet Por cliente
A1: Facturación por cliente (base imponible, sin IVA)
A2: Año | B2: =Configuración!$B$13 -> 2026 | C2: (se cambia en Configuración)
A4: Cliente | B4: Ene | C4: Feb | D4: Mar | E4: Abr | F4: May | G4: Jun | H4: Jul | I4: Ago | J4: Sep | K4: Oct | L4: Nov | M4: Dic | N4: Total año | O4: % del total
A5: =IF(Configuración!A16="","",Configuración!A16) -> Cliente A (ejemplo) | B5: =IF($A5="","",SUMIFS(Cobros!$F$2:$F$501,Cobros!$B$2:$B$501,$A5,Cobros!$A$2:$A$501,">="&DATE($B$2,1,1),Cobros!$A$2:$A$501,"<"&DATE($B$2,1+1,1))) -> 0 | C5: =IF($A5="","",SUMIFS(Cobros!$F$2:$F$501,Cobros!$B$2:$B$501,$A5,Cobros!$A$2:$A$501,">="&DATE($B$2,2,1),Cobros!$A$2:$A$501,"<"&DATE($B$2,2+1,1))) -> 0 | D5: =IF($A5="","",SUMIFS(Cobros!$F$2:$F$501,Cobros!$B$2:$B$501,$A5,Cobros!$A$2:$A$501,">="&DATE($B$2,3,1),Cobros!$A$2:$A$501,"<"&DATE($B$2,3+1,1))) -> 0 | E5: =IF($A5="","",SUMIFS(Cobros!$F$2:$F$501,Cobros!$B$2:$B$501,$A5,Cobros!$A$2:$A$501,">="&DATE($B$2,4,1),Cobros!$A$2:$A$501,"<"&DATE($B$2,4+1,1))) -> 0 | F5: =IF($A5="","",SUMIFS(Cobros!$F$2:$F$501,Cobros!$B$2:$B$501,$A5,Cobros!$A$2:$A$501,">="&DATE($B$2,5,1),Cobros!$A$2:$A$501,"<"&DATE($B$2,5+1,1))) -> 0 | G5: =IF($A5="","",SUMIFS(Cobros!$F$2:$F$501,Cobros!$B$2:$B$501,$A5,Cobros!$A$2:$A$501,">="&DATE($B$2,6,1),Cobros!$A$2:$A$501,"<"&DATE($B$2,6+1,1))) -> 0 | H5: =IF($A5="","",SUMIFS(Cobros!$F$2:$F$501,Cobros!$B$2:$B$501,$A5,Cobros!$A$2:$A$501,">="&DATE($B$2,7,1),Cobros!$A$2:$A$501,"<"&DATE($B$2,7+1,1))) -> 0 | I5: =IF($A5="","",SUMIFS(Cobros!$F$2:$F$501,Cobros!$B$2:$B$501,$A5,Cobros!$A$2:$A$501,">="&DATE($B$2,8,1),Cobros!$A$2:$A$501,"<"&DATE($B$2,8+1,1))) -> 0 | J5: =IF($A5="","",SUMIFS(Cobros!$F$2:$F$501,Cobros!$B$2:$B$501,$A5,Cobros!$A$2:$A$501,">="&DATE($B$2,9,1),Cobros!$A$2:$A$501,"<"&DATE($B$2,9+1,1))) -> 1200 | K5: =IF($A5="","",SUMIFS(Cobros!$F$2:$F$501,Cobros!$B$2:$B$501,$A5,Cobros!$A$2:$A$501,">="&DATE($B$2,10,1),Cobros!$A$2:$A$501,"<"&DATE($B$2,10+1,1))) -> 1200 | L5: =IF($A5="","",SUMIFS(Cobros!$F$2:$F$501,Cobros!$B$2:$B$501,$A5,Cobros!$A$2:$A$501,">="&DATE($B$2,11,1),Cobros!$A$2:$A$501,"<"&DATE($B$2,11+1,1))) -> 0 | M5: =IF($A5="","",SUMIFS(Cobros!$F$2:$F$501,Cobros!$B$2:$B$501,$A5,Cobros!$A$2:$A$501,">="&DATE($B$2,12,1),Cobros!$A$2:$A$501,"<"&DATE($B$2,12+1,1))) -> 0 | N5: =IF($A5="","",SUM(B5:M5)) -> 2400 | O5: =IF($A5="","",IF($N$35=0,0,N5/$N$35)) -> 0.43636364
A6: =IF(Configuración!A17="","",Configuración!A17) -> Cliente B (ejemplo) | B6: =IF($A6="","",SUMIFS(Cobros!$F$2:$F$501,Cobros!$B$2:$B$501,$A6,Cobros!$A$2:$A$501,">="&DATE($B$2,1,1),Cobros!$A$2:$A$501,"<"&DATE($B$2,1+1,1))) -> 0 | C6: =IF($A6="","",SUMIFS(Cobros!$F$2:$F$501,Cobros!$B$2:$B$501,$A6,Cobros!$A$2:$A$501,">="&DATE($B$2,2,1),Cobros!$A$2:$A$501,"<"&DATE($B$2,2+1,1))) -> 0 | D6: =IF($A6="","",SUMIFS(Cobros!$F$2:$F$501,Cobros!$B$2:$B$501,$A6,Cobros!$A$2:$A$501,">="&DATE($B$2,3,1),Cobros!$A$2:$A$501,"<"&DATE($B$2,3+1,1))) -> 0 | E6: =IF($A6="","",SUMIFS(Cobros!$F$2:$F$501,Cobros!$B$2:$B$501,$A6,Cobros!$A$2:$A$501,">="&DATE($B$2,4,1),Cobros!$A$2:$A$501,"<"&DATE($B$2,4+1,1))) -> 0 | F6: =IF($A6="","",SUMIFS(Cobros!$F$2:$F$501,Cobros!$B$2:$B$501,$A6,Cobros!$A$2:$A$501,">="&DATE($B$2,5,1),Cobros!$A$2:$A$501,"<"&DATE($B$2,5+1,1))) -> 0 | G6: =IF($A6="","",SUMIFS(Cobros!$F$2:$F$501,Cobros!$B$2:$B$501,$A6,Cobros!$A$2:$A$501,">="&DATE($B$2,6,1),Cobros!$A$2:$A$501,"<"&DATE($B$2,6+1,1))) -> 0 | H6: =IF($A6="","",SUMIFS(Cobros!$F$2:$F$501,Cobros!$B$2:$B$501,$A6,Cobros!$A$2:$A$501,">="&DATE($B$2,7,1),Cobros!$A$2:$A$501,"<"&DATE($B$2,7+1,1))) -> 0 | I6: =IF($A6="","",SUMIFS(Cobros!$F$2:$F$501,Cobros!$B$2:$B$501,$A6,Cobros!$A$2:$A$501,">="&DATE($B$2,8,1),Cobros!$A$2:$A$501,"<"&DATE($B$2,8+1,1))) -> 0 | J6: =IF($A6="","",SUMIFS(Cobros!$F$2:$F$501,Cobros!$B$2:$B$501,$A6,Cobros!$A$2:$A$501,">="&DATE($B$2,9,1),Cobros!$A$2:$A$501,"<"&DATE($B$2,9+1,1))) -> 800 | K6: =IF($A6="","",SUMIFS(Cobros!$F$2:$F$501,Cobros!$B$2:$B$501,$A6,Cobros!$A$2:$A$501,">="&DATE($B$2,10,1),Cobros!$A$2:$A$501,"<"&DATE($B$2,10+1,1))) -> 800 | L6: =IF($A6="","",SUMIFS(Cobros!$F$2:$F$501,Cobros!$B$2:$B$501,$A6,Cobros!$A$2:$A$501,">="&DATE($B$2,11,1),Cobros!$A$2:$A$501,"<"&DATE($B$2,11+1,1))) -> 0 | M6: =IF($A6="","",SUMIFS(Cobros!$F$2:$F$501,Cobros!$B$2:$B$501,$A6,Cobros!$A$2:$A$501,">="&DATE($B$2,12,1),Cobros!$A$2:$A$501,"<"&DATE($B$2,12+1,1))) -> 0 | N6: =IF($A6="","",SUM(B6:M6)) -> 1600 | O6: =IF($A6="","",IF($N$35=0,0,N6/$N$35)) -> 0.29090909
A7: =IF(Configuración!A18="","",Configuración!A18) -> Cliente C (ejemplo) | B7: =IF($A7="","",SUMIFS(Cobros!$F$2:$F$501,Cobros!$B$2:$B$501,$A7,Cobros!$A$2:$A$501,">="&DATE($B$2,1,1),Cobros!$A$2:$A$501,"<"&DATE($B$2,1+1,1))) -> 0 | C7: =IF($A7="","",SUMIFS(Cobros!$F$2:$F$501,Cobros!$B$2:$B$501,$A7,Cobros!$A$2:$A$501,">="&DATE($B$2,2,1),Cobros!$A$2:$A$501,"<"&DATE($B$2,2+1,1))) -> 0 | D7: =IF($A7="","",SUMIFS(Cobros!$F$2:$F$501,Cobros!$B$2:$B$501,$A7,Cobros!$A$2:$A$501,">="&DATE($B$2,3,1),Cobros!$A$2:$A$501,"<"&DATE($B$2,3+1,1))) -> 0 | E7: =IF($A7="","",SUMIFS(Cobros!$F$2:$F$501,Cobros!$B$2:$B$501,$A7,Cobros!$A$2:$A$501,">="&DATE($B$2,4,1),Cobros!$A$2:$A$501,"<"&DATE($B$2,4+1,1))) -> 0 | F7: =IF($A7="","",SUMIFS(Cobros!$F$2:$F$501,Cobros!$B$2:$B$501,$A7,Cobros!$A$2:$A$501,">="&DATE($B$2,5,1),Cobros!$A$2:$A$501,"<"&DATE($B$2,5+1,1))) -> 0 | G7: =IF($A7="","",SUMIFS(Cobros!$F$2:$F$501,Cobros!$B$2:$B$501,$A7,Cobros!$A$2:$A$501,">="&DATE($B$2,6,1),Cobros!$A$2:$A$501,"<"&DATE($B$2,6+1,1))) -> 0 | H7: =IF($A7="","",SUMIFS(Cobros!$F$2:$F$501,Cobros!$B$2:$B$501,$A7,Cobros!$A$2:$A$501,">="&DATE($B$2,7,1),Cobros!$A$2:$A$501,"<"&DATE($B$2,7+1,1))) -> 0 | I7: =IF($A7="","",SUMIFS(Cobros!$F$2:$F$501,Cobros!$B$2:$B$501,$A7,Cobros!$A$2:$A$501,">="&DATE($B$2,8,1),Cobros!$A$2:$A$501,"<"&DATE($B$2,8+1,1))) -> 0 | J7: =IF($A7="","",SUMIFS(Cobros!$F$2:$F$501,Cobros!$B$2:$B$501,$A7,Cobros!$A$2:$A$501,">="&DATE($B$2,9,1),Cobros!$A$2:$A$501,"<"&DATE($B$2,9+1,1))) -> 0 | K7: =IF($A7="","",SUMIFS(Cobros!$F$2:$F$501,Cobros!$B$2:$B$501,$A7,Cobros!$A$2:$A$501,">="&DATE($B$2,10,1),Cobros!$A$2:$A$501,"<"&DATE($B$2,10+1,1))) -> 1500 | L7: =IF($A7="","",SUMIFS(Cobros!$F$2:$F$501,Cobros!$B$2:$B$501,$A7,Cobros!$A$2:$A$501,">="&DATE($B$2,11,1),Cobros!$A$2:$A$501,"<"&DATE($B$2,11+1,1))) -> 0 | M7: =IF($A7="","",SUMIFS(Cobros!$F$2:$F$501,Cobros!$B$2:$B$501,$A7,Cobros!$A$2:$A$501,">="&DATE($B$2,12,1),Cobros!$A$2:$A$501,"<"&DATE($B$2,12+1,1))) -> 0 | N7: =IF($A7="","",SUM(B7:M7)) -> 1500 | O7: =IF($A7="","",IF($N$35=0,0,N7/$N$35)) -> 0.27272727
A8: =IF(Configuración!A19="","",Configuración!A19) -> Cliente D (ejemplo) | B8: =IF($A8="","",SUMIFS(Cobros!$F$2:$F$501,Cobros!$B$2:$B$501,$A8,Cobros!$A$2:$A$501,">="&DATE($B$2,1,1),Cobros!$A$2:$A$501,"<"&DATE($B$2,1+1,1))) -> 0 | C8: =IF($A8="","",SUMIFS(Cobros!$F$2:$F$501,Cobros!$B$2:$B$501,$A8,Cobros!$A$2:$A$501,">="&DATE($B$2,2,1),Cobros!$A$2:$A$501,"<"&DATE($B$2,2+1,1))) -> 0 | D8: =IF($A8="","",SUMIFS(Cobros!$F$2:$F$501,Cobros!$B$2:$B$501,$A8,Cobros!$A$2:$A$501,">="&DATE($B$2,3,1),Cobros!$A$2:$A$501,"<"&DATE($B$2,3+1,1))) -> 0 | E8: =IF($A8="","",SUMIFS(Cobros!$F$2:$F$501,Cobros!$B$2:$B$501,$A8,Cobros!$A$2:$A$501,">="&DATE($B$2,4,1),Cobros!$A$2:$A$501,"<"&DATE($B$2,4+1,1))) -> 0 | F8: =IF($A8="","",SUMIFS(Cobros!$F$2:$F$501,Cobros!$B$2:$B$501,$A8,Cobros!$A$2:$A$501,">="&DATE($B$2,5,1),Cobros!$A$2:$A$501,"<"&DATE($B$2,5+1,1))) -> 0 | G8: =IF($A8="","",SUMIFS(Cobros!$F$2:$F$501,Cobros!$B$2:$B$501,$A8,Cobros!$A$2:$A$501,">="&DATE($B$2,6,1),Cobros!$A$2:$A$501,"<"&DATE($B$2,6+1,1))) -> 0 | H8: =IF($A8="","",SUMIFS(Cobros!$F$2:$F$501,Cobros!$B$2:$B$501,$A8,Cobros!$A$2:$A$501,">="&DATE($B$2,7,1),Cobros!$A$2:$A$501,"<"&DATE($B$2,7+1,1))) -> 0 | I8: =IF($A8="","",SUMIFS(Cobros!$F$2:$F$501,Cobros!$B$2:$B$501,$A8,Cobros!$A$2:$A$501,">="&DATE($B$2,8,1),Cobros!$A$2:$A$501,"<"&DATE($B$2,8+1,1))) -> 0 | J8: =IF($A8="","",SUMIFS(Cobros!$F$2:$F$501,Cobros!$B$2:$B$501,$A8,Cobros!$A$2:$A$501,">="&DATE($B$2,9,1),Cobros!$A$2:$A$501,"<"&DATE($B$2,9+1,1))) -> 0 | K8: =IF($A8="","",SUMIFS(Cobros!$F$2:$F$501,Cobros!$B$2:$B$501,$A8,Cobros!$A$2:$A$501,">="&DATE($B$2,10,1),Cobros!$A$2:$A$501,"<"&DATE($B$2,10+1,1))) -> 0 | L8: =IF($A8="","",SUMIFS(Cobros!$F$2:$F$501,Cobros!$B$2:$B$501,$A8,Cobros!$A$2:$A$501,">="&DATE($B$2,11,1),Cobros!$A$2:$A$501,"<"&DATE($B$2,11+1,1))) -> 0 | M8: =IF($A8="","",SUMIFS(Cobros!$F$2:$F$501,Cobros!$B$2:$B$501,$A8,Cobros!$A$2:$A$501,">="&DATE($B$2,12,1),Cobros!$A$2:$A$501,"<"&DATE($B$2,12+1,1))) -> 0 | N8: =IF($A8="","",SUM(B8:M8)) -> 0 | O8: =IF($A8="","",IF($N$35=0,0,N8/$N$35)) -> 0
A9: =IF(Configuración!A20="","",Configuración!A20) | B9: =IF($A9="","",SUMIFS(Cobros!$F$2:$F$501,Cobros!$B$2:$B$501,$A9,Cobros!$A$2:$A$501,">="&DATE($B$2,1,1),Cobros!$A$2:$A$501,"<"&DATE($B$2,1+1,1))) | C9: =IF($A9="","",SUMIFS(Cobros!$F$2:$F$501,Cobros!$B$2:$B$501,$A9,Cobros!$A$2:$A$501,">="&DATE($B$2,2,1),Cobros!$A$2:$A$501,"<"&DATE($B$2,2+1,1))) | D9: =IF($A9="","",SUMIFS(Cobros!$F$2:$F$501,Cobros!$B$2:$B$501,$A9,Cobros!$A$2:$A$501,">="&DATE($B$2,3,1),Cobros!$A$2:$A$501,"<"&DATE($B$2,3+1,1))) | E9: =IF($A9="","",SUMIFS(Cobros!$F$2:$F$501,Cobros!$B$2:$B$501,$A9,Cobros!$A$2:$A$501,">="&DATE($B$2,4,1),Cobros!$A$2:$A$501,"<"&DATE($B$2,4+1,1))) | F9: =IF($A9="","",SUMIFS(Cobros!$F$2:$F$501,Cobros!$B$2:$B$501,$A9,Cobros!$A$2:$A$501,">="&DATE($B$2,5,1),Cobros!$A$2:$A$501,"<"&DATE($B$2,5+1,1))) | G9: =IF($A9="","",SUMIFS(Cobros!$F$2:$F$501,Cobros!$B$2:$B$501,$A9,Cobros!$A$2:$A$501,">="&DATE($B$2,6,1),Cobros!$A$2:$A$501,"<"&DATE($B$2,6+1,1))) | H9: =IF($A9="","",SUMIFS(Cobros!$F$2:$F$501,Cobros!$B$2:$B$501,$A9,Cobros!$A$2:$A$501,">="&DATE($B$2,7,1),Cobros!$A$2:$A$501,"<"&DATE($B$2,7+1,1))) | I9: =IF($A9="","",SUMIFS(Cobros!$F$2:$F$501,Cobros!$B$2:$B$501,$A9,Cobros!$A$2:$A$501,">="&DATE($B$2,8,1),Cobros!$A$2:$A$501,"<"&DATE($B$2,8+1,1))) | J9: =IF($A9="","",SUMIFS(Cobros!$F$2:$F$501,Cobros!$B$2:$B$501,$A9,Cobros!$A$2:$A$501,">="&DATE($B$2,9,1),Cobros!$A$2:$A$501,"<"&DATE($B$2,9+1,1))) | K9: =IF($A9="","",SUMIFS(Cobros!$F$2:$F$501,Cobros!$B$2:$B$501,$A9,Cobros!$A$2:$A$501,">="&DATE($B$2,10,1),Cobros!$A$2:$A$501,"<"&DATE($B$2,10+1,1))) | L9: =IF($A9="","",SUMIFS(Cobros!$F$2:$F$501,Cobros!$B$2:$B$501,$A9,Cobros!$A$2:$A$501,">="&DATE($B$2,11,1),Cobros!$A$2:$A$501,"<"&DATE($B$2,11+1,1))) | M9: =IF($A9="","",SUMIFS(Cobros!$F$2:$F$501,Cobros!$B$2:$B$501,$A9,Cobros!$A$2:$A$501,">="&DATE($B$2,12,1),Cobros!$A$2:$A$501,"<"&DATE($B$2,12+1,1))) | N9: =IF($A9="","",SUM(B9:M9)) | O9: =IF($A9="","",IF($N$35=0,0,N9/$N$35))
A10: =IF(Configuración!A21="","",Configuración!A21) | B10: =IF($A10="","",SUMIFS(Cobros!$F$2:$F$501,Cobros!$B$2:$B$501,$A10,Cobros!$A$2:$A$501,">="&DATE($B$2,1,1),Cobros!$A$2:$A$501,"<"&DATE($B$2,1+1,1))) | C10: =IF($A10="","",SUMIFS(Cobros!$F$2:$F$501,Cobros!$B$2:$B$501,$A10,Cobros!$A$2:$A$501,">="&DATE($B$2,2,1),Cobros!$A$2:$A$501,"<"&DATE($B$2,2+1,1))) | D10: =IF($A10="","",SUMIFS(Cobros!$F$2:$F$501,Cobros!$B$2:$B$501,$A10,Cobros!$A$2:$A$501,">="&DATE($B$2,3,1),Cobros!$A$2:$A$501,"<"&DATE($B$2,3+1,1))) | E10: =IF($A10="","",SUMIFS(Cobros!$F$2:$F$501,Cobros!$B$2:$B$501,$A10,Cobros!$A$2:$A$501,">="&DATE($B$2,4,1),Cobros!$A$2:$A$501,"<"&DATE($B$2,4+1,1))) | F10: =IF($A10="","",SUMIFS(Cobros!$F$2:$F$501,Cobros!$B$2:$B$501,$A10,Cobros!$A$2:$A$501,">="&DATE($B$2,5,1),Cobros!$A$2:$A$501,"<"&DATE($B$2,5+1,1))) | G10: =IF($A10="","",SUMIFS(Cobros!$F$2:$F$501,Cobros!$B$2:$B$501,$A10,Cobros!$A$2:$A$501,">="&DATE($B$2,6,1),Cobros!$A$2:$A$501,"<"&DATE($B$2,6+1,1))) | H10: =IF($A10="","",SUMIFS(Cobros!$F$2:$F$501,Cobros!$B$2:$B$501,$A10,Cobros!$A$2:$A$501,">="&DATE($B$2,7,1),Cobros!$A$2:$A$501,"<"&DATE($B$2,7+1,1))) | I10: =IF($A10="","",SUMIFS(Cobros!$F$2:$F$501,Cobros!$B$2:$B$501,$A10,Cobros!$A$2:$A$501,">="&DATE($B$2,8,1),Cobros!$A$2:$A$501,"<"&DATE($B$2,8+1,1))) | J10: =IF($A10="","",SUMIFS(Cobros!$F$2:$F$501,Cobros!$B$2:$B$501,$A10,Cobros!$A$2:$A$501,">="&DATE($B$2,9,1),Cobros!$A$2:$A$501,"<"&DATE($B$2,9+1,1))) | K10: =IF($A10="","",SUMIFS(Cobros!$F$2:$F$501,Cobros!$B$2:$B$501,$A10,Cobros!$A$2:$A$501,">="&DATE($B$2,10,1),Cobros!$A$2:$A$501,"<"&DATE($B$2,10+1,1))) | L10: =IF($A10="","",SUMIFS(Cobros!$F$2:$F$501,Cobros!$B$2:$B$501,$A10,Cobros!$A$2:$A$501,">="&DATE($B$2,11,1),Cobros!$A$2:$A$501,"<"&DATE($B$2,11+1,1))) | M10: =IF($A10="","",SUMIFS(Cobros!$F$2:$F$501,Cobros!$B$2:$B$501,$A10,Cobros!$A$2:$A$501,">="&DATE($B$2,12,1),Cobros!$A$2:$A$501,"<"&DATE($B$2,12+1,1))) | N10: =IF($A10="","",SUM(B10:M10)) | O10: =IF($A10="","",IF($N$35=0,0,N10/$N$35))
